Workbook

Sheet 개요
A1: 조선 4사 외환·파생손익 트래킹 (IFRS 18 대응)
A3: 목적: IFRS 18 적용 시 영업손익 아래(투자·재무 범주)로 표시되는 외환손익·파생손익의 기간별 추적
A5: 데이터: DART 분기·반기·사업보고서 재무제표 주석 (금융수익·비용 / 기타수익·비용 세부 항목)
A6: 단위: 백만원 / 연결재무제표 주석 기준 (연결 주석이 없는 기간만 별도 기준, 열 머리글에 * 표시)
A7: 같은 기간에 기재정정본이 있으면 최신 제출본 사용
A9: 시트 구성: 회사별 (누적) = 각 보고서에 기재된 당기 누적치 원본
A10: 회사별 (분기) = 누적 차감으로 계산한 분기 순수 실적 (수식으로 연결됨)
A12: 항목 정의:
A13: 외환차익/차손 = 외화거래 결제 시 실현 손익
A14: 외화환산이익/손실 = 화폐성 외화자산·부채 기말 환산 손익 (미실현)
A15: 파생거래이익/손실 = 파생상품(통화선도 등) 정산 실현 손익
A16: 파생평가이익/손실 = 파생상품 기말 공정가치 평가 손익 (미실현)
... A21: 손실 항목은 주석에 양수로 기재된 값 그대로이며, 순손익 계산 시 차감

Sheet HD한국조선해양(누적)
A1: HD한국조선해양 외환·파생손익 — 보고서 누적치
A2: (단위: 백만원, 각 열은 해당 보고서의 당기 누적. *=별도 기준)
A4: 항목 | B4: 2015.12 | C4: 2016.09 | D4: 2016.12 | E4: 2017.03 | F4: 2017.06 | G4: 2017.09 | H4: 2017.12 | I4: 2018.03 | J4: 2018.06 | K4: 2018.09 | L4: 2018.12 | M4: 2019.03* | N4: 2019.06 | O4: 2019.09 | P4: 2019.12 | Q4: 2020.03 | R4: 2020.06 | S4: 2020.09 | T4: 2020.12 | U4: 2021.03 | V4: 2021.06 | W4: 2021.09 | X4: 2021.12 | Y4: 2022.03 | Z4: 2022.06 | AA4: 2022.09 | AB4: 2022.12 | AC4: 2023.03 | AD4: 2023.06 | AE4: 2023.09 | AF4: 2023.12 | AG4: 2024.03 | AH4: 2024.06 | AI4: 2024.09 | AJ4: 2024.12 | AK4: 2025.03 | AL4: 2025.06 | AM4: 2025.09 | AN4: 2025.12 | AO4: 2026.03 | AP4: 2026.06
A5: 외환차익 | B5: 894811 | C5: 757909 | D5: 953863 | E5: 134129 | F5: 227611 | G5: 366398 | H5: 511468 | I5: 81914 | J5: 182771 | K5: 283619 | L5: 361452 | M5: 38477 | N5: 254568 | O5: 333414 | P5: 400389 | Q5: 215024 | R5: 361316 | S5: 446899 | T5: 539290 | U5: 155534 | V5: 283023 | W5: 435245 | X5: 562313 | Y5: 118432 | Z5: 393152 | AA5: 782563 | AB5: 1225012 | AC5: 169088 | AD5: 364230 | AE5: 546940 | AF5: 719563 | AG5: 203433 | AH5: 505672 | AI5: 661060 | AJ5: 946909 | AK5: 162258 | AL5: 404157 | AM5: 580209 | AN5: 813602 | AO5: 364975 | AP5: 813378
A6: 외환차손 | B6: 939590 | C6: 753704 | D6: 928920 | E6: 267633 | F6: 440767 | G6: 562884 | H6: 708041 | I6: 90111 | J6: 166318 | K6: 259058 | L6: 325461 | M6: 32405 | N6: 212367 | O6: 275779 | P6: 361015 | Q6: 134664 | R6: 248900 | S6: 349728 | T6: 526117 | U6: 91417 | V6: 183564 | W6: 263928 | X6: 378287 | Y6: 82004 | Z6: 209894 | AA6: 365466 | AB6: 712219 | AC6: 162231 | AD6: 276569 | AE6: 388931 | AF6: 536892 | AG6: 98554 | AH6: 220362 | AI6: 364358 | AJ6: 480673 | AK6: 236630 | AL6: 709543 | AM6: 992317 | AN6: 1154336 | AO6: 217365 | AP6: 471962
A7: 외화환산이익 | B7: 245016 | C7: 334343 | D7: 123202 | E7: 280610 | F7: 168629 | G7: 107602 | H7: 156996 | I7: 21655 | J7: 93514 | K7: 39232 | L7: 40011 | M7: 28111 | N7: 61849 | O7: 46339 | P7: 60707 | Q7: 186292 | R7: 88178 | S7: 46343 | T7: 154653 | U7: 156530 | V7: 84226 | W7: 231978 | X7: 159028 | Y7: 96615 | Z7: 371359 | AA7: 881795 | AB7: 96413 | AC7: 181716 | AD7: 146905 | AE7: 263739 | AF7: 31710 | AG7: 241717 | AH7: 286958 | AI7: 45221 | AJ7: 576005 | AK7: 52531 | AL7: 104928 | AM7: 99811 | AN7: 151137 | AO7: 381838 | AP7: 517337
A8: 외화환산손실 | B8: 299363 | C8: 193972 | D8: 232285 | E8: 296836 | F8: 122284 | G8: 83261 | H8: 126179 | I8: 20974 | J8: 96771 | K8: 58036 | L8: 52286 | M8: 19636 | N8: 75596 | O8: 45148 | P8: 44770 | Q8: 121015 | R8: 70765 | S8: 36782 | T8: 320302 | U8: 70031 | V8: 53969 | W8: 162095 | X8: 111454 | Y8: 55420 | Z8: 225100 | AA8: 527758 | AB8: 438266 | AC8: 66574 | AD8: 71994 | AE8: 118773 | AF8: 164973 | AG8: 74042 | AH8: 100901 | AI8: 204377 | AJ8: 183763 | AK8: 27360 | AL8: 438088 | AM8: 98472 | AN8: 88226 | AO8: 91407 | AP8: 234184
A9: 파생거래이익 | B9: 101735 | C9: 174391 | D9: 199816 | E9: 157530 | F9: 282173 | G9: 347474 | H9: 432361 | I9: 8199 | J9: 11576 | K9: 13288 | L9: 17984 | M9: 664 | N9: 5789 | O9: 12666 | P9: 30327 | Q9: 3799 | R9: 14086 | S9: 35625 | T9: 93840 | U9: 10017 | V9: 24783 | W9: 31001 | X9: 48278 | Y9: 3698 | Z9: 9259 | AA9: 29049 | AB9: 104625 | AC9: 50827 | AD9: 68149 | AE9: 94792 | AF9: 129772 | AG9: 31490 | AH9: 39643 | AI9: 70547 | AJ9: 79350 | AK9: 45478 | AL9: 224670 | AM9: 379481 | AN9: 424880 | AO9: 7346 | AP9: 18412
A10: 파생거래손실 | B10: 364438 | C10: 108503 | D10: 144797 | E10: 2725 | F10: 35962 | G10: 16793 | H10: 18219 | I10: 5501 | J10: 20668 | K10: 55743 | L10: 133693 | M10: 13866 | N10: 71731 | O10: 113175 | P10: 142499 | Q10: 84980 | R10: 175014 | S10: 222725 | T10: 230872 | U10: 58628 | V10: 100947 | W10: 153641 | X10: 170811 | Y10: 33549 | Z10: 145144 | AA10: 288422 | AB10: 677871 | AC10: 82395 | AD10: 229129 | AE10: 401402 | AF10: 562497 | AG10: 140834 | AH10: 374790 | AI10: 556895 | AJ10: 867987 | AK10: 10911 | AL10: 21622 | AM10: 42135 | AN10: 130143 | AO10: 106161 | AP10: 297787
A11: 파생평가이익 | B11: 14419 | C11: 507791 | D11: 1658 | E11: 401004 | F11: 200769 | G11: 104801 | H11: 223768 | I11: 26829 | J11: 6150 | K11: 20382 | L11: 26324 | M11: 8654 | N11: 155502 | O11: 58962 | P11: 189013 | Q11: 42286 | R11: 50536 | S11: 55563 | T11: 444732 | U11: 24487 | V11: 27653 | W11: 76853 | X11: 80399 | Y11: 57528 | Z11: 148353 | AA11: 294346 | AB11: 588396 | AC11: 29061 | AD11: 66470 | AE11: 62759 | AF11: 136916 | AG11: 28267 | AH11: 31004 | AI11: 156285 | AJ11: 55546 | AK11: 2965 | AL11: 1859876 | AM11: 606687 | AN11: 73238 | AO11: 28217 | AP11: 42147
A12: 파생평가손실 | B12: 681181 | C12: 483 | D12: 215892 | E12: 143 | F12: 8652 | G12: 23704 | H12: 161 | I12: 2742 | J12: 212256 | K12: 165642 | L12: 148838 | M12: 76443 | N12: 362799 | O12: 529124 | P12: 352693 | Q12: 443255 | R12: 296725 | S12: 145327 | T12: 39040 | U12: 260704 | V12: 244015 | W12: 790396 | X12: 785840 | Y12: 157416 | Z12: 1371978 | AA12: 3676348 | AB12: 797215 | AC12: 746743 | AD12: 773216 | AE12: 1355775 | AF12: 481666 | AG12: 1093081 | AH12: 1824588 | AI12: 750586 | AJ12: 3439846 | AK12: 232374 | AL12: 36190 | AM12: 154732 | AN12: 529080 | AO12: 1775566 | AP12: 2383148
A13: 순외환손익 | B13: ='HD한국조선해양(누적)'!B5+'HD한국조선해양(누적)'!B7-'HD한국조선해양(누적)'!B6-'HD한국조선해양(누적)'!B8 | C13: ='HD한국조선해양(누적)'!C5+'HD한국조선해양(누적)'!C7-'HD한국조선해양(누적)'!C6-'HD한국조선해양(누적)'!C8 | D13: ='HD한국조선해양(누적)'!D5+'HD한국조선해양(누적)'!D7-'HD한국조선해양(누적)'!D6-'HD한국조선해양(누적)'!D8 | E13: ='HD한국조선해양(누적)'!E5+'HD한국조선해양(누적)'!E7-'HD한국조선해양(누적)'!E6-'HD한국조선해양(누적)'!E8 | F13: ='HD한국조선해양(누적)'!F5+'HD한국조선해양(누적)'!F7-'HD한국조선해양(누적)'!F6-'HD한국조선해양(누적)'!F8 | G13: ='HD한국조선해양(누적)'!G5+'HD한국조선해양(누적)'!G7-'HD한국조선해양(누적)'!G6-'HD한국조선해양(누적)'!G8 | H13: ='HD한국조선해양(누적)'!H5+'HD한국조선해양(누적)'!H7-'HD한국조선해양(누적)'!H6-'HD한국조선해양(누적)'!H8 | I13: ='HD한국조선해양(누적)'!I5+'HD한국조선해양(누적)'!I7-'HD한국조선해양(누적)'!I6-'HD한국조선해양(누적)'!I8 | ... AP13: ='HD한국조선해양(누적)'!AP5+'HD한국조선해양(누적)'!AP7-'HD한국조선해양(누적)'!AP6-'HD한국조선해양(누적)'!AP8
A14: 순파생손익 | B14: ='HD한국조선해양(누적)'!B9+'HD한국조선해양(누적)'!B11-'HD한국조선해양(누적)'!B10-'HD한국조선해양(누적)'!B12 | C14: ='HD한국조선해양(누적)'!C9+'HD한국조선해양(누적)'!C11-'HD한국조선해양(누적)'!C10-'HD한국조선해양(누적)'!C12 | D14: ='HD한국조선해양(누적)'!D9+'HD한국조선해양(누적)'!D11-'HD한국조선해양(누적)'!D10-'HD한국조선해양(누적)'!D12 | E14: ='HD한국조선해양(누적)'!E9+'HD한국조선해양(누적)'!E11-'HD한국조선해양(누적)'!E10-'HD한국조선해양(누적)'!E12 | F14: ='HD한국조선해양(누적)'!F9+'HD한국조선해양(누적)'!F11-'HD한국조선해양(누적)'!F10-'HD한국조선해양(누적)'!F12 | G14: ='HD한국조선해양(누적)'!G9+'HD한국조선해양(누적)'!G11-'HD한국조선해양(누적)'!G10-'HD한국조선해양(누적)'!G12 | H14: ='HD한국조선해양(누적)'!H9+'HD한국조선해양(누적)'!H11-'HD한국조선해양(누적)'!H10-'HD한국조선해양(누적)'!H12 | I14: ='HD한국조선해양(누적)'!I9+'HD한국조선해양(누적)'!I11-'HD한국조선해양(누적)'!I10-'HD한국조선해양(누적)'!I12 | ... AP14: ='HD한국조선해양(누적)'!AP9+'HD한국조선해양(누적)'!AP11-'HD한국조선해양(누적)'!AP10-'HD한국조선해양(누적)'!AP12
A15: 총 순손익 | B15: ='HD한국조선해양(누적)'!B13+'HD한국조선해양(누적)'!B14 | C15: ='HD한국조선해양(누적)'!C13+'HD한국조선해양(누적)'!C14 | D15: ='HD한국조선해양(누적)'!D13+'HD한국조선해양(누적)'!D14 | E15: ='HD한국조선해양(누적)'!E13+'HD한국조선해양(누적)'!E14 | F15: ='HD한국조선해양(누적)'!F13+'HD한국조선해양(누적)'!F14 | G15: ='HD한국조선해양(누적)'!G13+'HD한국조선해양(누적)'!G14 | H15: ='HD한국조선해양(누적)'!H13+'HD한국조선해양(누적)'!H14 | I15: ='HD한국조선해양(누적)'!I13+'HD한국조선해양(누적)'!I14 | ... AP15: ='HD한국조선해양(누적)'!AP13+'HD한국조선해양(누적)'!AP14

Sheet HD한국조선해양(분기)
A1: HD한국조선해양 외환·파생손익 — 분기별(비누적)
A2: (단위: 백만원, 누적 차감 방식 — (누적) 시트 수식 참조. '~누적' 열은 이전 분기 보고서가 없어 누적값 그대로)
A4: 항목 | B4: 2015 ~4Q누적 | C4: 2016 ~3Q누적 | D4: 2016 4Q | E4: 2017 1Q | F4: 2017 2Q | G4: 2017 3Q | H4: 2017 4Q | I4: 2018 1Q | J4: 2018 2Q | K4: 2018 3Q | L4: 2018 4Q | M4: 2019 1Q | N4: 2019 2Q | O4: 2019 3Q | P4: 2019 4Q | Q4: 2020 1Q | R4: 2020 2Q | S4: 2020 3Q | T4: 2020 4Q | U4: 2021 1Q | V4: 2021 2Q | W4: 2021 3Q | X4: 2021 4Q | Y4: 2022 1Q | Z4: 2022 2Q | AA4: 2022 3Q | AB4: 2022 4Q | AC4: 2023 1Q | AD4: 2023 2Q | AE4: 2023 3Q | AF4: 2023 4Q | AG4: 2024 1Q | AH4: 2024 2Q | AI4: 2024 3Q | AJ4: 2024 4Q | AK4: 2025 1Q | AL4: 2025 2Q | AM4: 2025 3Q | AN4: 2025 4Q | AO4: 2026 1Q | AP4: 2026 2Q
A5: 외환차익 | B5: ='HD한국조선해양(누적)'!B5 | C5: ='HD한국조선해양(누적)'!C5 | D5: ='HD한국조선해양(누적)'!D5-'HD한국조선해양(누적)'!C5 | E5: ='HD한국조선해양(누적)'!E5 | F5: ='HD한국조선해양(누적)'!F5-'HD한국조선해양(누적)'!E5 | G5: ='HD한국조선해양(누적)'!G5-'HD한국조선해양(누적)'!F5 | H5: ='HD한국조선해양(누적)'!H5-'HD한국조선해양(누적)'!G5 | I5: ='HD한국조선해양(누적)'!I5 | J5: ='HD한국조선해양(누적)'!J5-'HD한국조선해양(누적)'!I5 | K5: ='HD한국조선해양(누적)'!K5-'HD한국조선해양(누적)'!J5 | L5: ='HD한국조선해양(누적)'!L5-'HD한국조선해양(누적)'!K5 | M5: ='HD한국조선해양(누적)'!M5 | N5: ='HD한국조선해양(누적)'!N5-'HD한국조선해양(누적)'!M5 | O5: ='HD한국조선해양(누적)'!O5-'HD한국조선해양(누적)'!N5 | P5: ='HD한국조선해양(누적)'!P5-'HD한국조선해양(누적)'!O5 | Q5: ='HD한국조선해양(누적)'!Q5 | R5: ='HD한국조선해양(누적)'!R5-'HD한국조선해양(누적)'!Q5 | S5: ='HD한국조선해양(누적)'!S5-'HD한국조선해양(누적)'!R5 | T5: ='HD한국조선해양(누적)'!T5-'HD한국조선해양(누적)'!S5 | U5: ='HD한국조선해양(누적)'!U5 | V5: ='HD한국조선해양(누적)'!V5-'HD한국조선해양(누적)'!U5 | W5: ='HD한국조선해양(누적)'!W5-'HD한국조선해양(누적)'!V5 | X5: ='HD한국조선해양(누적)'!X5-'HD한국조선해양(누적)'!W5 | Y5: ='HD한국조선해양(누적)'!Y5 | Z5: ='HD한국조선해양(누적)'!Z5-'HD한국조선해양(누적)'!Y5 | AA5: ='HD한국조선해양(누적)'!AA5-'HD한국조선해양(누적)'!Z5 | AB5: ='HD한국조선해양(누적)'!AB5-'HD한국조선해양(누적)'!AA5 | AC5: ='HD한국조선해양(누적)'!AC5 | AD5: ='HD한국조선해양(누적)'!AD5-'HD한국조선해양(누적)'!AC5 | AE5: ='HD한국조선해양(누적)'!AE5-'HD한국조선해양(누적)'!AD5 | AF5: ='HD한국조선해양(누적)'!AF5-'HD한국조선해양(누적)'!AE5 | AG5: ='HD한국조선해양(누적)'!AG5 | AH5: ='HD한국조선해양(누적)'!AH5-'HD한국조선해양(누적)'!AG5 | AI5: ='HD한국조선해양(누적)'!AI5-'HD한국조선해양(누적)'!AH5 | AJ5: ='HD한국조선해양(누적)'!AJ5-'HD한국조선해양(누적)'!AI5 | AK5: ='HD한국조선해양(누적)'!AK5 | AL5: ='HD한국조선해양(누적)'!AL5-'HD한국조선해양(누적)'!AK5 | AM5: ='HD한국조선해양(누적)'!AM5-'HD한국조선해양(누적)'!AL5 | AN5: ='HD한국조선해양(누적)'!AN5-'HD한국조선해양(누적)'!AM5 | AO5: ='HD한국조선해양(누적)'!AO5 | AP5: ='HD한국조선해양(누적)'!AP5-'HD한국조선해양(누적)'!AO5
A6: 외환차손 | B6: ='HD한국조선해양(누적)'!B6 | C6: ='HD한국조선해양(누적)'!C6 | D6: ='HD한국조선해양(누적)'!D6-'HD한국조선해양(누적)'!C6 | E6: ='HD한국조선해양(누적)'!E6 | F6: ='HD한국조선해양(누적)'!F6-'HD한국조선해양(누적)'!E6 | G6: ='HD한국조선해양(누적)'!G6-'HD한국조선해양(누적)'!F6 | H6: ='HD한국조선해양(누적)'!H6-'HD한국조선해양(누적)'!G6 | I6: ='HD한국조선해양(누적)'!I6 | J6: ='HD한국조선해양(누적)'!J6-'HD한국조선해양(누적)'!I6 | K6: ='HD한국조선해양(누적)'!K6-'HD한국조선해양(누적)'!J6 | L6: ='HD한국조선해양(누적)'!L6-'HD한국조선해양(누적)'!K6 | M6: ='HD한국조선해양(누적)'!M6 | N6: ='HD한국조선해양(누적)'!N6-'HD한국조선해양(누적)'!M6 | O6: ='HD한국조선해양(누적)'!O6-'HD한국조선해양(누적)'!N6 | P6: ='HD한국조선해양(누적)'!P6-'HD한국조선해양(누적)'!O6 | Q6: ='HD한국조선해양(누적)'!Q6 | R6: ='HD한국조선해양(누적)'!R6-'HD한국조선해양(누적)'!Q6 | S6: ='HD한국조선해양(누적)'!S6-'HD한국조선해양(누적)'!R6 | T6: ='HD한국조선해양(누적)'!T6-'HD한국조선해양(누적)'!S6 | U6: ='HD한국조선해양(누적)'!U6 | V6: ='HD한국조선해양(누적)'!V6-'HD한국조선해양(누적)'!U6 | W6: ='HD한국조선해양(누적)'!W6-'HD한국조선해양(누적)'!V6 | X6: ='HD한국조선해양(누적)'!X6-'HD한국조선해양(누적)'!W6 | Y6: ='HD한국조선해양(누적)'!Y6 | Z6: ='HD한국조선해양(누적)'!Z6-'HD한국조선해양(누적)'!Y6 | AA6: ='HD한국조선해양(누적)'!AA6-'HD한국조선해양(누적)'!Z6 | AB6: ='HD한국조선해양(누적)'!AB6-'HD한국조선해양(누적)'!AA6 | AC6: ='HD한국조선해양(누적)'!AC6 | AD6: ='HD한국조선해양(누적)'!AD6-'HD한국조선해양(누적)'!AC6 | AE6: ='HD한국조선해양(누적)'!AE6-'HD한국조선해양(누적)'!AD6 | AF6: ='HD한국조선해양(누적)'!AF6-'HD한국조선해양(누적)'!AE6 | AG6: ='HD한국조선해양(누적)'!AG6 | AH6: ='HD한국조선해양(누적)'!AH6-'HD한국조선해양(누적)'!AG6 | AI6: ='HD한국조선해양(누적)'!AI6-'HD한국조선해양(누적)'!AH6 | AJ6: ='HD한국조선해양(누적)'!AJ6-'HD한국조선해양(누적)'!AI6 | AK6: ='HD한국조선해양(누적)'!AK6 | AL6: ='HD한국조선해양(누적)'!AL6-'HD한국조선해양(누적)'!AK6 | AM6: ='HD한국조선해양(누적)'!AM6-'HD한국조선해양(누적)'!AL6 | AN6: ='HD한국조선해양(누적)'!AN6-'HD한국조선해양(누적)'!AM6 | AO6: ='HD한국조선해양(누적)'!AO6 | AP6: ='HD한국조선해양(누적)'!AP6-'HD한국조선해양(누적)'!AO6
A7: 외화환산이익 | B7: ='HD한국조선해양(누적)'!B7 | C7: ='HD한국조선해양(누적)'!C7 | D7: ='HD한국조선해양(누적)'!D7-'HD한국조선해양(누적)'!C7 | E7: ='HD한국조선해양(누적)'!E7 | F7: ='HD한국조선해양(누적)'!F7-'HD한국조선해양(누적)'!E7 | G7: ='HD한국조선해양(누적)'!G7-'HD한국조선해양(누적)'!F7 | H7: ='HD한국조선해양(누적)'!H7-'HD한국조선해양(누적)'!G7 | I7: ='HD한국조선해양(누적)'!I7 | J7: ='HD한국조선해양(누적)'!J7-'HD한국조선해양(누적)'!I7 | K7: ='HD한국조선해양(누적)'!K7-'HD한국조선해양(누적)'!J7 | L7: ='HD한국조선해양(누적)'!L7-'HD한국조선해양(누적)'!K7 | M7: ='HD한국조선해양(누적)'!M7 | N7: ='HD한국조선해양(누적)'!N7-'HD한국조선해양(누적)'!M7 | O7: ='HD한국조선해양(누적)'!O7-'HD한국조선해양(누적)'!N7 | P7: ='HD한국조선해양(누적)'!P7-'HD한국조선해양(누적)'!O7 | Q7: ='HD한국조선해양(누적)'!Q7 | R7: ='HD한국조선해양(누적)'!R7-'HD한국조선해양(누적)'!Q7 | S7: ='HD한국조선해양(누적)'!S7-'HD한국조선해양(누적)'!R7 | T7: ='HD한국조선해양(누적)'!T7-'HD한국조선해양(누적)'!S7 | U7: ='HD한국조선해양(누적)'!U7 | V7: ='HD한국조선해양(누적)'!V7-'HD한국조선해양(누적)'!U7 | W7: ='HD한국조선해양(누적)'!W7-'HD한국조선해양(누적)'!V7 | X7: ='HD한국조선해양(누적)'!X7-'HD한국조선해양(누적)'!W7 | Y7: ='HD한국조선해양(누적)'!Y7 | Z7: ='HD한국조선해양(누적)'!Z7-'HD한국조선해양(누적)'!Y7 | AA7: ='HD한국조선해양(누적)'!AA7-'HD한국조선해양(누적)'!Z7 | AB7: ='HD한국조선해양(누적)'!AB7-'HD한국조선해양(누적)'!AA7 | AC7: ='HD한국조선해양(누적)'!AC7 | AD7: ='HD한국조선해양(누적)'!AD7-'HD한국조선해양(누적)'!AC7 | AE7: ='HD한국조선해양(누적)'!AE7-'HD한국조선해양(누적)'!AD7 | AF7: ='HD한국조선해양(누적)'!AF7-'HD한국조선해양(누적)'!AE7 | AG7: ='HD한국조선해양(누적)'!AG7 | AH7: ='HD한국조선해양(누적)'!AH7-'HD한국조선해양(누적)'!AG7 | AI7: ='HD한국조선해양(누적)'!AI7-'HD한국조선해양(누적)'!AH7 | AJ7: ='HD한국조선해양(누적)'!AJ7-'HD한국조선해양(누적)'!AI7 | AK7: ='HD한국조선해양(누적)'!AK7 | AL7: ='HD한국조선해양(누적)'!AL7-'HD한국조선해양(누적)'!AK7 | AM7: ='HD한국조선해양(누적)'!AM7-'HD한국조선해양(누적)'!AL7 | AN7: ='HD한국조선해양(누적)'!AN7-'HD한국조선해양(누적)'!AM7 | AO7: ='HD한국조선해양(누적)'!AO7 | AP7: ='HD한국조선해양(누적)'!AP7-'HD한국조선해양(누적)'!AO7
A8: 외화환산손실 | B8: ='HD한국조선해양(누적)'!B8 | C8: ='HD한국조선해양(누적)'!C8 | D8: ='HD한국조선해양(누적)'!D8-'HD한국조선해양(누적)'!C8 | E8: ='HD한국조선해양(누적)'!E8 | F8: ='HD한국조선해양(누적)'!F8-'HD한국조선해양(누적)'!E8 | G8: ='HD한국조선해양(누적)'!G8-'HD한국조선해양(누적)'!F8 | H8: ='HD한국조선해양(누적)'!H8-'HD한국조선해양(누적)'!G8 | I8: ='HD한국조선해양(누적)'!I8 | J8: ='HD한국조선해양(누적)'!J8-'HD한국조선해양(누적)'!I8 | K8: ='HD한국조선해양(누적)'!K8-'HD한국조선해양(누적)'!J8 | L8: ='HD한국조선해양(누적)'!L8-'HD한국조선해양(누적)'!K8 | M8: ='HD한국조선해양(누적)'!M8 | N8: ='HD한국조선해양(누적)'!N8-'HD한국조선해양(누적)'!M8 | O8: ='HD한국조선해양(누적)'!O8-'HD한국조선해양(누적)'!N8 | P8: ='HD한국조선해양(누적)'!P8-'HD한국조선해양(누적)'!O8 | Q8: ='HD한국조선해양(누적)'!Q8 | R8: ='HD한국조선해양(누적)'!R8-'HD한국조선해양(누적)'!Q8 | S8: ='HD한국조선해양(누적)'!S8-'HD한국조선해양(누적)'!R8 | T8: ='HD한국조선해양(누적)'!T8-'HD한국조선해양(누적)'!S8 | U8: ='HD한국조선해양(누적)'!U8 | V8: ='HD한국조선해양(누적)'!V8-'HD한국조선해양(누적)'!U8 | W8: ='HD한국조선해양(누적)'!W8-'HD한국조선해양(누적)'!V8 | X8: ='HD한국조선해양(누적)'!X8-'HD한국조선해양(누적)'!W8 | Y8: ='HD한국조선해양(누적)'!Y8 | Z8: ='HD한국조선해양(누적)'!Z8-'HD한국조선해양(누적)'!Y8 | AA8: ='HD한국조선해양(누적)'!AA8-'HD한국조선해양(누적)'!Z8 | AB8: ='HD한국조선해양(누적)'!AB8-'HD한국조선해양(누적)'!AA8 | AC8: ='HD한국조선해양(누적)'!AC8 | AD8: ='HD한국조선해양(누적)'!AD8-'HD한국조선해양(누적)'!AC8 | AE8: ='HD한국조선해양(누적)'!AE8-'HD한국조선해양(누적)'!AD8 | AF8: ='HD한국조선해양(누적)'!AF8-'HD한국조선해양(누적)'!AE8 | AG8: ='HD한국조선해양(누적)'!AG8 | AH8: ='HD한국조선해양(누적)'!AH8-'HD한국조선해양(누적)'!AG8 | AI8: ='HD한국조선해양(누적)'!AI8-'HD한국조선해양(누적)'!AH8 | AJ8: ='HD한국조선해양(누적)'!AJ8-'HD한국조선해양(누적)'!AI8 | AK8: ='HD한국조선해양(누적)'!AK8 | AL8: ='HD한국조선해양(누적)'!AL8-'HD한국조선해양(누적)'!AK8 | AM8: ='HD한국조선해양(누적)'!AM8-'HD한국조선해양(누적)'!AL8 | AN8: ='HD한국조선해양(누적)'!AN8-'HD한국조선해양(누적)'!AM8 | AO8: ='HD한국조선해양(누적)'!AO8 | AP8: ='HD한국조선해양(누적)'!AP8-'HD한국조선해양(누적)'!AO8
A9: 파생거래이익 | B9: ='HD한국조선해양(누적)'!B9 | C9: ='HD한국조선해양(누적)'!C9 | D9: ='HD한국조선해양(누적)'!D9-'HD한국조선해양(누적)'!C9 | E9: ='HD한국조선해양(누적)'!E9 | F9: ='HD한국조선해양(누적)'!F9-'HD한국조선해양(누적)'!E9 | G9: ='HD한국조선해양(누적)'!G9-'HD한국조선해양(누적)'!F9 | H9: ='HD한국조선해양(누적)'!H9-'HD한국조선해양(누적)'!G9 | I9: ='HD한국조선해양(누적)'!I9 | J9: ='HD한국조선해양(누적)'!J9-'HD한국조선해양(누적)'!I9 | K9: ='HD한국조선해양(누적)'!K9-'HD한국조선해양(누적)'!J9 | L9: ='HD한국조선해양(누적)'!L9-'HD한국조선해양(누적)'!K9 | M9: ='HD한국조선해양(누적)'!M9 | N9: ='HD한국조선해양(누적)'!N9-'HD한국조선해양(누적)'!M9 | O9: ='HD한국조선해양(누적)'!O9-'HD한국조선해양(누적)'!N9 | P9: ='HD한국조선해양(누적)'!P9-'HD한국조선해양(누적)'!O9 | Q9: ='HD한국조선해양(누적)'!Q9 | R9: ='HD한국조선해양(누적)'!R9-'HD한국조선해양(누적)'!Q9 | S9: ='HD한국조선해양(누적)'!S9-'HD한국조선해양(누적)'!R9 | T9: ='HD한국조선해양(누적)'!T9-'HD한국조선해양(누적)'!S9 | U9: ='HD한국조선해양(누적)'!U9 | V9: ='HD한국조선해양(누적)'!V9-'HD한국조선해양(누적)'!U9 | W9: ='HD한국조선해양(누적)'!W9-'HD한국조선해양(누적)'!V9 | X9: ='HD한국조선해양(누적)'!X9-'HD한국조선해양(누적)'!W9 | Y9: ='HD한국조선해양(누적)'!Y9 | Z9: ='HD한국조선해양(누적)'!Z9-'HD한국조선해양(누적)'!Y9 | AA9: ='HD한국조선해양(누적)'!AA9-'HD한국조선해양(누적)'!Z9 | AB9: ='HD한국조선해양(누적)'!AB9-'HD한국조선해양(누적)'!AA9 | AC9: ='HD한국조선해양(누적)'!AC9 | AD9: ='HD한국조선해양(누적)'!AD9-'HD한국조선해양(누적)'!AC9 | AE9: ='HD한국조선해양(누적)'!AE9-'HD한국조선해양(누적)'!AD9 | AF9: ='HD한국조선해양(누적)'!AF9-'HD한국조선해양(누적)'!AE9 | AG9: ='HD한국조선해양(누적)'!AG9 | AH9: ='HD한국조선해양(누적)'!AH9-'HD한국조선해양(누적)'!AG9 | AI9: ='HD한국조선해양(누적)'!AI9-'HD한국조선해양(누적)'!AH9 | AJ9: ='HD한국조선해양(누적)'!AJ9-'HD한국조선해양(누적)'!AI9 | AK9: ='HD한국조선해양(누적)'!AK9 | AL9: ='HD한국조선해양(누적)'!AL9-'HD한국조선해양(누적)'!AK9 | AM9: ='HD한국조선해양(누적)'!AM9-'HD한국조선해양(누적)'!AL9 | AN9: ='HD한국조선해양(누적)'!AN9-'HD한국조선해양(누적)'!AM9 | AO9: ='HD한국조선해양(누적)'!AO9 | AP9: ='HD한국조선해양(누적)'!AP9-'HD한국조선해양(누적)'!AO9
A10: 파생거래손실 | B10: ='HD한국조선해양(누적)'!B10 | C10: ='HD한국조선해양(누적)'!C10 | D10: ='HD한국조선해양(누적)'!D10-'HD한국조선해양(누적)'!C10 | E10: ='HD한국조선해양(누적)'!E10 | F10: ='HD한국조선해양(누적)'!F10-'HD한국조선해양(누적)'!E10 | G10: ='HD한국조선해양(누적)'!G10-'HD한국조선해양(누적)'!F10 | H10: ='HD한국조선해양(누적)'!H10-'HD한국조선해양(누적)'!G10 | I10: ='HD한국조선해양(누적)'!I10 | J10: ='HD한국조선해양(누적)'!J10-'HD한국조선해양(누적)'!I10 | K10: ='HD한국조선해양(누적)'!K10-'HD한국조선해양(누적)'!J10 | L10: ='HD한국조선해양(누적)'!L10-'HD한국조선해양(누적)'!K10 | M10: ='HD한국조선해양(누적)'!M10 | N10: ='HD한국조선해양(누적)'!N10-'HD한국조선해양(누적)'!M10 | O10: ='HD한국조선해양(누적)'!O10-'HD한국조선해양(누적)'!N10 | P10: ='HD한국조선해양(누적)'!P10-'HD한국조선해양(누적)'!O10 | Q10: ='HD한국조선해양(누적)'!Q10 | R10: ='HD한국조선해양(누적)'!R10-'HD한국조선해양(누적)'!Q10 | S10: ='HD한국조선해양(누적)'!S10-'HD한국조선해양(누적)'!R10 | T10: ='HD한국조선해양(누적)'!T10-'HD한국조선해양(누적)'!S10 | U10: ='HD한국조선해양(누적)'!U10 | V10: ='HD한국조선해양(누적)'!V10-'HD한국조선해양(누적)'!U10 | W10: ='HD한국조선해양(누적)'!W10-'HD한국조선해양(누적)'!V10 | X10: ='HD한국조선해양(누적)'!X10-'HD한국조선해양(누적)'!W10 | Y10: ='HD한국조선해양(누적)'!Y10 | Z10: ='HD한국조선해양(누적)'!Z10-'HD한국조선해양(누적)'!Y10 | AA10: ='HD한국조선해양(누적)'!AA10-'HD한국조선해양(누적)'!Z10 | AB10: ='HD한국조선해양(누적)'!AB10-'HD한국조선해양(누적)'!AA10 | AC10: ='HD한국조선해양(누적)'!AC10 | AD10: ='HD한국조선해양(누적)'!AD10-'HD한국조선해양(누적)'!AC10 | AE10: ='HD한국조선해양(누적)'!AE10-'HD한국조선해양(누적)'!AD10 | AF10: ='HD한국조선해양(누적)'!AF10-'HD한국조선해양(누적)'!AE10 | AG10: ='HD한국조선해양(누적)'!AG10 | AH10: ='HD한국조선해양(누적)'!AH10-'HD한국조선해양(누적)'!AG10 | AI10: ='HD한국조선해양(누적)'!AI10-'HD한국조선해양(누적)'!AH10 | AJ10: ='HD한국조선해양(누적)'!AJ10-'HD한국조선해양(누적)'!AI10 | AK10: ='HD한국조선해양(누적)'!AK10 | AL10: ='HD한국조선해양(누적)'!AL10-'HD한국조선해양(누적)'!AK10 | AM10: ='HD한국조선해양(누적)'!AM10-'HD한국조선해양(누적)'!AL10 | AN10: ='HD한국조선해양(누적)'!AN10-'HD한국조선해양(누적)'!AM10 | AO10: ='HD한국조선해양(누적)'!AO10 | AP10: ='HD한국조선해양(누적)'!AP10-'HD한국조선해양(누적)'!AO10
A11: 파생평가이익 | B11: ='HD한국조선해양(누적)'!B11 | C11: ='HD한국조선해양(누적)'!C11 | D11: ='HD한국조선해양(누적)'!D11-'HD한국조선해양(누적)'!C11 | E11: ='HD한국조선해양(누적)'!E11 | F11: ='HD한국조선해양(누적)'!F11-'HD한국조선해양(누적)'!E11 | G11: ='HD한국조선해양(누적)'!G11-'HD한국조선해양(누적)'!F11 | H11: ='HD한국조선해양(누적)'!H11-'HD한국조선해양(누적)'!G11 | I11: ='HD한국조선해양(누적)'!I11 | J11: ='HD한국조선해양(누적)'!J11-'HD한국조선해양(누적)'!I11 | K11: ='HD한국조선해양(누적)'!K11-'HD한국조선해양(누적)'!J11 | L11: ='HD한국조선해양(누적)'!L11-'HD한국조선해양(누적)'!K11 | M11: ='HD한국조선해양(누적)'!M11 | N11: ='HD한국조선해양(누적)'!N11-'HD한국조선해양(누적)'!M11 | O11: ='HD한국조선해양(누적)'!O11-'HD한국조선해양(누적)'!N11 | P11: ='HD한국조선해양(누적)'!P11-'HD한국조선해양(누적)'!O11 | Q11: ='HD한국조선해양(누적)'!Q11 | R11: ='HD한국조선해양(누적)'!R11-'HD한국조선해양(누적)'!Q11 | S11: ='HD한국조선해양(누적)'!S11-'HD한국조선해양(누적)'!R11 | T11: ='HD한국조선해양(누적)'!T11-'HD한국조선해양(누적)'!S11 | U11: ='HD한국조선해양(누적)'!U11 | V11: ='HD한국조선해양(누적)'!V11-'HD한국조선해양(누적)'!U11 | W11: ='HD한국조선해양(누적)'!W11-'HD한국조선해양(누적)'!V11 | X11: ='HD한국조선해양(누적)'!X11-'HD한국조선해양(누적)'!W11 | Y11: ='HD한국조선해양(누적)'!Y11 | Z11: ='HD한국조선해양(누적)'!Z11-'HD한국조선해양(누적)'!Y11 | AA11: ='HD한국조선해양(누적)'!AA11-'HD한국조선해양(누적)'!Z11 | AB11: ='HD한국조선해양(누적)'!AB11-'HD한국조선해양(누적)'!AA11 | AC11: ='HD한국조선해양(누적)'!AC11 | AD11: ='HD한국조선해양(누적)'!AD11-'HD한국조선해양(누적)'!AC11 | AE11: ='HD한국조선해양(누적)'!AE11-'HD한국조선해양(누적)'!AD11 | AF11: ='HD한국조선해양(누적)'!AF11-'HD한국조선해양(누적)'!AE11 | AG11: ='HD한국조선해양(누적)'!AG11 | AH11: ='HD한국조선해양(누적)'!AH11-'HD한국조선해양(누적)'!AG11 | AI11: ='HD한국조선해양(누적)'!AI11-'HD한국조선해양(누적)'!AH11 | AJ11: ='HD한국조선해양(누적)'!AJ11-'HD한국조선해양(누적)'!AI11 | AK11: ='HD한국조선해양(누적)'!AK11 | AL11: ='HD한국조선해양(누적)'!AL11-'HD한국조선해양(누적)'!AK11 | AM11: ='HD한국조선해양(누적)'!AM11-'HD한국조선해양(누적)'!AL11 | AN11: ='HD한국조선해양(누적)'!AN11-'HD한국조선해양(누적)'!AM11 | AO11: ='HD한국조선해양(누적)'!AO11 | AP11: ='HD한국조선해양(누적)'!AP11-'HD한국조선해양(누적)'!AO11
A12: 파생평가손실 | B12: ='HD한국조선해양(누적)'!B12 | C12: ='HD한국조선해양(누적)'!C12 | D12: ='HD한국조선해양(누적)'!D12-'HD한국조선해양(누적)'!C12 | E12: ='HD한국조선해양(누적)'!E12 | F12: ='HD한국조선해양(누적)'!F12-'HD한국조선해양(누적)'!E12 | G12: ='HD한국조선해양(누적)'!G12-'HD한국조선해양(누적)'!F12 | H12: ='HD한국조선해양(누적)'!H12-'HD한국조선해양(누적)'!G12 | I12: ='HD한국조선해양(누적)'!I12 | J12: ='HD한국조선해양(누적)'!J12-'HD한국조선해양(누적)'!I12 | K12: ='HD한국조선해양(누적)'!K12-'HD한국조선해양(누적)'!J12 | L12: ='HD한국조선해양(누적)'!L12-'HD한국조선해양(누적)'!K12 | M12: ='HD한국조선해양(누적)'!M12 | N12: ='HD한국조선해양(누적)'!N12-'HD한국조선해양(누적)'!M12 | O12: ='HD한국조선해양(누적)'!O12-'HD한국조선해양(누적)'!N12 | P12: ='HD한국조선해양(누적)'!P12-'HD한국조선해양(누적)'!O12 | Q12: ='HD한국조선해양(누적)'!Q12 | R12: ='HD한국조선해양(누적)'!R12-'HD한국조선해양(누적)'!Q12 | S12: ='HD한국조선해양(누적)'!S12-'HD한국조선해양(누적)'!R12 | T12: ='HD한국조선해양(누적)'!T12-'HD한국조선해양(누적)'!S12 | U12: ='HD한국조선해양(누적)'!U12 | V12: ='HD한국조선해양(누적)'!V12-'HD한국조선해양(누적)'!U12 | W12: ='HD한국조선해양(누적)'!W12-'HD한국조선해양(누적)'!V12 | X12: ='HD한국조선해양(누적)'!X12-'HD한국조선해양(누적)'!W12 | Y12: ='HD한국조선해양(누적)'!Y12 | Z12: ='HD한국조선해양(누적)'!Z12-'HD한국조선해양(누적)'!Y12 | AA12: ='HD한국조선해양(누적)'!AA12-'HD한국조선해양(누적)'!Z12 | AB12: ='HD한국조선해양(누적)'!AB12-'HD한국조선해양(누적)'!AA12 | AC12: ='HD한국조선해양(누적)'!AC12 | AD12: ='HD한국조선해양(누적)'!AD12-'HD한국조선해양(누적)'!AC12 | AE12: ='HD한국조선해양(누적)'!AE12-'HD한국조선해양(누적)'!AD12 | AF12: ='HD한국조선해양(누적)'!AF12-'HD한국조선해양(누적)'!AE12 | AG12: ='HD한국조선해양(누적)'!AG12 | AH12: ='HD한국조선해양(누적)'!AH12-'HD한국조선해양(누적)'!AG12 | AI12: ='HD한국조선해양(누적)'!AI12-'HD한국조선해양(누적)'!AH12 | AJ12: ='HD한국조선해양(누적)'!AJ12-'HD한국조선해양(누적)'!AI12 | AK12: ='HD한국조선해양(누적)'!AK12 | AL12: ='HD한국조선해양(누적)'!AL12-'HD한국조선해양(누적)'!AK12 | AM12: ='HD한국조선해양(누적)'!AM12-'HD한국조선해양(누적)'!AL12 | AN12: ='HD한국조선해양(누적)'!AN12-'HD한국조선해양(누적)'!AM12 | AO12: ='HD한국조선해양(누적)'!AO12 | AP12: ='HD한국조선해양(누적)'!AP12-'HD한국조선해양(누적)'!AO12
A13: 순외환손익 | B13: ='HD한국조선해양(누적)'!B13 | C13: ='HD한국조선해양(누적)'!C13 | D13: ='HD한국조선해양(누적)'!D13-'HD한국조선해양(누적)'!C13 | E13: ='HD한국조선해양(누적)'!E13 | F13: ='HD한국조선해양(누적)'!F13-'HD한국조선해양(누적)'!E13 | G13: ='HD한국조선해양(누적)'!G13-'HD한국조선해양(누적)'!F13 | H13: ='HD한국조선해양(누적)'!H13-'HD한국조선해양(누적)'!G13 | I13: ='HD한국조선해양(누적)'!I13 | J13: ='HD한국조선해양(누적)'!J13-'HD한국조선해양(누적)'!I13 | K13: ='HD한국조선해양(누적)'!K13-'HD한국조선해양(누적)'!J13 | L13: ='HD한국조선해양(누적)'!L13-'HD한국조선해양(누적)'!K13 | M13: ='HD한국조선해양(누적)'!M13 | N13: ='HD한국조선해양(누적)'!N13-'HD한국조선해양(누적)'!M13 | O13: ='HD한국조선해양(누적)'!O13-'HD한국조선해양(누적)'!N13 | P13: ='HD한국조선해양(누적)'!P13-'HD한국조선해양(누적)'!O13 | Q13: ='HD한국조선해양(누적)'!Q13 | R13: ='HD한국조선해양(누적)'!R13-'HD한국조선해양(누적)'!Q13 | S13: ='HD한국조선해양(누적)'!S13-'HD한국조선해양(누적)'!R13 | T13: ='HD한국조선해양(누적)'!T13-'HD한국조선해양(누적)'!S13 | U13: ='HD한국조선해양(누적)'!U13 | V13: ='HD한국조선해양(누적)'!V13-'HD한국조선해양(누적)'!U13 | W13: ='HD한국조선해양(누적)'!W13-'HD한국조선해양(누적)'!V13 | X13: ='HD한국조선해양(누적)'!X13-'HD한국조선해양(누적)'!W13 | Y13: ='HD한국조선해양(누적)'!Y13 | Z13: ='HD한국조선해양(누적)'!Z13-'HD한국조선해양(누적)'!Y13 | AA13: ='HD한국조선해양(누적)'!AA13-'HD한국조선해양(누적)'!Z13 | AB13: ='HD한국조선해양(누적)'!AB13-'HD한국조선해양(누적)'!AA13 | AC13: ='HD한국조선해양(누적)'!AC13 | AD13: ='HD한국조선해양(누적)'!AD13-'HD한국조선해양(누적)'!AC13 | AE13: ='HD한국조선해양(누적)'!AE13-'HD한국조선해양(누적)'!AD13 | AF13: ='HD한국조선해양(누적)'!AF13-'HD한국조선해양(누적)'!AE13 | AG13: ='HD한국조선해양(누적)'!AG13 | AH13: ='HD한국조선해양(누적)'!AH13-'HD한국조선해양(누적)'!AG13 | AI13: ='HD한국조선해양(누적)'!AI13-'HD한국조선해양(누적)'!AH13 | AJ13: ='HD한국조선해양(누적)'!AJ13-'HD한국조선해양(누적)'!AI13 | AK13: ='HD한국조선해양(누적)'!AK13 | AL13: ='HD한국조선해양(누적)'!AL13-'HD한국조선해양(누적)'!AK13 | AM13: ='HD한국조선해양(누적)'!AM13-'HD한국조선해양(누적)'!AL13 | AN13: ='HD한국조선해양(누적)'!AN13-'HD한국조선해양(누적)'!AM13 | AO13: ='HD한국조선해양(누적)'!AO13 | AP13: ='HD한국조선해양(누적)'!AP13-'HD한국조선해양(누적)'!AO13
A14: 순파생손익 | B14: ='HD한국조선해양(누적)'!B14 | C14: ='HD한국조선해양(누적)'!C14 | D14: ='HD한국조선해양(누적)'!D14-'HD한국조선해양(누적)'!C14 | E14: ='HD한국조선해양(누적)'!E14 | F14: ='HD한국조선해양(누적)'!F14-'HD한국조선해양(누적)'!E14 | G14: ='HD한국조선해양(누적)'!G14-'HD한국조선해양(누적)'!F14 | H14: ='HD한국조선해양(누적)'!H14-'HD한국조선해양(누적)'!G14 | I14: ='HD한국조선해양(누적)'!I14 | J14: ='HD한국조선해양(누적)'!J14-'HD한국조선해양(누적)'!I14 | K14: ='HD한국조선해양(누적)'!K14-'HD한국조선해양(누적)'!J14 | L14: ='HD한국조선해양(누적)'!L14-'HD한국조선해양(누적)'!K14 | M14: ='HD한국조선해양(누적)'!M14 | N14: ='HD한국조선해양(누적)'!N14-'HD한국조선해양(누적)'!M14 | O14: ='HD한국조선해양(누적)'!O14-'HD한국조선해양(누적)'!N14 | P14: ='HD한국조선해양(누적)'!P14-'HD한국조선해양(누적)'!O14 | Q14: ='HD한국조선해양(누적)'!Q14 | R14: ='HD한국조선해양(누적)'!R14-'HD한국조선해양(누적)'!Q14 | S14: ='HD한국조선해양(누적)'!S14-'HD한국조선해양(누적)'!R14 | T14: ='HD한국조선해양(누적)'!T14-'HD한국조선해양(누적)'!S14 | U14: ='HD한국조선해양(누적)'!U14 | V14: ='HD한국조선해양(누적)'!V14-'HD한국조선해양(누적)'!U14 | W14: ='HD한국조선해양(누적)'!W14-'HD한국조선해양(누적)'!V14 | X14: ='HD한국조선해양(누적)'!X14-'HD한국조선해양(누적)'!W14 | Y14: ='HD한국조선해양(누적)'!Y14 | Z14: ='HD한국조선해양(누적)'!Z14-'HD한국조선해양(누적)'!Y14 | AA14: ='HD한국조선해양(누적)'!AA14-'HD한국조선해양(누적)'!Z14 | AB14: ='HD한국조선해양(누적)'!AB14-'HD한국조선해양(누적)'!AA14 | AC14: ='HD한국조선해양(누적)'!AC14 | AD14: ='HD한국조선해양(누적)'!AD14-'HD한국조선해양(누적)'!AC14 | AE14: ='HD한국조선해양(누적)'!AE14-'HD한국조선해양(누적)'!AD14 | AF14: ='HD한국조선해양(누적)'!AF14-'HD한국조선해양(누적)'!AE14 | AG14: ='HD한국조선해양(누적)'!AG14 | AH14: ='HD한국조선해양(누적)'!AH14-'HD한국조선해양(누적)'!AG14 | AI14: ='HD한국조선해양(누적)'!AI14-'HD한국조선해양(누적)'!AH14 | AJ14: ='HD한국조선해양(누적)'!AJ14-'HD한국조선해양(누적)'!AI14 | AK14: ='HD한국조선해양(누적)'!AK14 | AL14: ='HD한국조선해양(누적)'!AL14-'HD한국조선해양(누적)'!AK14 | AM14: ='HD한국조선해양(누적)'!AM14-'HD한국조선해양(누적)'!AL14 | AN14: ='HD한국조선해양(누적)'!AN14-'HD한국조선해양(누적)'!AM14 | AO14: ='HD한국조선해양(누적)'!AO14 | AP14: ='HD한국조선해양(누적)'!AP14-'HD한국조선해양(누적)'!AO14
A15: 총 순손익 | B15: ='HD한국조선해양(누적)'!B15 | C15: ='HD한국조선해양(누적)'!C15 | D15: ='HD한국조선해양(누적)'!D15-'HD한국조선해양(누적)'!C15 | E15: ='HD한국조선해양(누적)'!E15 | F15: ='HD한국조선해양(누적)'!F15-'HD한국조선해양(누적)'!E15 | G15: ='HD한국조선해양(누적)'!G15-'HD한국조선해양(누적)'!F15 | H15: ='HD한국조선해양(누적)'!H15-'HD한국조선해양(누적)'!G15 | I15: ='HD한국조선해양(누적)'!I15 | J15: ='HD한국조선해양(누적)'!J15-'HD한국조선해양(누적)'!I15 | K15: ='HD한국조선해양(누적)'!K15-'HD한국조선해양(누적)'!J15 | L15: ='HD한국조선해양(누적)'!L15-'HD한국조선해양(누적)'!K15 | M15: ='HD한국조선해양(누적)'!M15 | N15: ='HD한국조선해양(누적)'!N15-'HD한국조선해양(누적)'!M15 | O15: ='HD한국조선해양(누적)'!O15-'HD한국조선해양(누적)'!N15 | P15: ='HD한국조선해양(누적)'!P15-'HD한국조선해양(누적)'!O15 | Q15: ='HD한국조선해양(누적)'!Q15 | R15: ='HD한국조선해양(누적)'!R15-'HD한국조선해양(누적)'!Q15 | S15: ='HD한국조선해양(누적)'!S15-'HD한국조선해양(누적)'!R15 | T15: ='HD한국조선해양(누적)'!T15-'HD한국조선해양(누적)'!S15 | U15: ='HD한국조선해양(누적)'!U15 | V15: ='HD한국조선해양(누적)'!V15-'HD한국조선해양(누적)'!U15 | W15: ='HD한국조선해양(누적)'!W15-'HD한국조선해양(누적)'!V15 | X15: ='HD한국조선해양(누적)'!X15-'HD한국조선해양(누적)'!W15 | Y15: ='HD한국조선해양(누적)'!Y15 | Z15: ='HD한국조선해양(누적)'!Z15-'HD한국조선해양(누적)'!Y15 | AA15: ='HD한국조선해양(누적)'!AA15-'HD한국조선해양(누적)'!Z15 | AB15: ='HD한국조선해양(누적)'!AB15-'HD한국조선해양(누적)'!AA15 | AC15: ='HD한국조선해양(누적)'!AC15 | AD15: ='HD한국조선해양(누적)'!AD15-'HD한국조선해양(누적)'!AC15 | AE15: ='HD한국조선해양(누적)'!AE15-'HD한국조선해양(누적)'!AD15 | AF15: ='HD한국조선해양(누적)'!AF15-'HD한국조선해양(누적)'!AE15 | AG15: ='HD한국조선해양(누적)'!AG15 | AH15: ='HD한국조선해양(누적)'!AH15-'HD한국조선해양(누적)'!AG15 | AI15: ='HD한국조선해양(누적)'!AI15-'HD한국조선해양(누적)'!AH15 | AJ15: ='HD한국조선해양(누적)'!AJ15-'HD한국조선해양(누적)'!AI15 | AK15: ='HD한국조선해양(누적)'!AK15 | AL15: ='HD한국조선해양(누적)'!AL15-'HD한국조선해양(누적)'!AK15 | AM15: ='HD한국조선해양(누적)'!AM15-'HD한국조선해양(누적)'!AL15 | AN15: ='HD한국조선해양(누적)'!AN15-'HD한국조선해양(누적)'!AM15 | AO15: ='HD한국조선해양(누적)'!AO15 | AP15: ='HD한국조선해양(누적)'!AP15-'HD한국조선해양(누적)'!AO15

Sheet HD현대중공업(누적)
A1: HD현대중공업 외환·파생손익 — 보고서 누적치
A2: (단위: 백만원, 각 열은 해당 보고서의 당기 누적. *=별도 기준)
A4: 항목 | B4: 2020.12 | C4: 2021.03 | D4: 2021.06 | E4: 2021.09 | F4: 2021.12 | G4: 2022.03 | H4: 2022.06 | I4: 2022.09 | J4: 2022.12 | K4: 2023.03 | L4: 2023.06 | M4: 2023.09 | N4: 2023.12 | O4: 2024.03 | P4: 2024.06 | Q4: 2024.09 | R4: 2024.12 | S4: 2025.03 | T4: 2025.06 | U4: 2025.09 | V4: 2025.12 | W4: 2026.03 | X4: 2026.06
A5: 외환차익 | B5: 255848 | C5: 83872 | D5: 145399 | E5: 219453 | F5: 292079 | G5: 48052 | H5: 180099 | I5: 373613 | J5: 563126 | K5: 66962 | L5: 154800 | M5: 236938 | N5: 328263 | O5: 90906 | P5: 237438 | Q5: 314547 | R5: 457065 | S5: 73119 | T5: 204039 | U5: 288332 | V5: 399083 | W5: 216779 | X5: 462242
A6: 외환차손 | B6: 234772 | C6: 53351 | D6: 100050 | E6: 139020 | F6: 210359 | G6: 39613 | H6: 108783 | I6: 189749 | J6: 361088 | K6: 75169 | L6: 122088 | M6: 180522 | N6: 252512 | O6: 57133 | P6: 129059 | Q6: 188824 | R6: 255021 | S6: 120963 | T6: 370907 | U6: 516509 | V6: 603695 | W6: 127228 | X6: 261260
A7: 외화환산이익 | B7: 110363 | C7: 78525 | D7: 45619 | E7: 121780 | F7: 91658 | G7: 56878 | H7: 197953 | I7: 437865 | J7: 48520 | K7: 100387 | L7: 87036 | M7: 156664 | N7: 19804 | O7: 136929 | P7: 174869 | Q7: 31440 | R7: 326939 | S7: 30846 | T7: 62605 | U7: 58349 | V7: 87654 | W7: 267689 | X7: 286201
A8: 외화환산손실 | B8: 201834 | C8: 47942 | D8: 38214 | E8: 113944 | F8: 84741 | G8: 38027 | H8: 165733 | I8: 378045 | J8: 227849 | K8: 42797 | L8: 54481 | M8: 90910 | N8: 85326 | O8: 53537 | P8: 71109 | Q8: 110377 | R8: 116402 | S8: 14850 | T8: 235699 | U8: 62925 | V8: 83877 | W8: 67250 | X8: 82090
A9: 파생거래이익 | B9: 60529 | C9: 5664 | D9: 11792 | E9: 16886 | F9: 31288 | G9: 1814 | H9: 4299 | I9: 8061 | J9: 62607 | K9: 37205 | L9: 48322 | M9: 65597 | N9: 93561 | O9: 16861 | P9: 35862 | Q9: 62579 | R9: 70557 | S9: 32062 | T9: 156468 | U9: 259553 | V9: 299913 | W9: 6318 | X9: 16575
A10: 파생거래손실 | B10: 142494 | C10: 33056 | D10: 67928 | E10: 96708 | F10: 99460 | G10: 18868 | H10: 87657 | I10: 167078 | J10: 460267 | K10: 52356 | L10: 138393 | M10: 235784 | N10: 336524 | O10: 65249 | P10: 235052 | Q10: 354065 | R10: 560931 | S10: 7797 | T10: 16112 | U10: 36128 | V10: 111726 | W10: 78334 | X10: 218148
A11: 파생평가이익 | B11: 297341 | C11: 24330 | D11: 24296 | E11: 73629 | F11: 72741 | G11: 50088 | H11: 143498 | I11: 288358 | J11: 410328 | K11: 26830 | L11: 55529 | M11: 60216 | N11: 99596 | O11: 28139 | P11: 30988 | Q11: 116030 | R11: 55268 | S11: 2899 | T11: 1152653 | U11: 376339 | V11: 118123 | W11: 26808 | X11: 40629
A12: 파생평가손실 | B12: 38397 | C12: 148408 | D12: 124686 | E12: 464428 | F12: 470564 | G12: 76381 | H12: 801433 | I12: 2240279 | J12: 415425 | K12: 458827 | L12: 471569 | M12: 849800 | N12: 315113 | O12: 698045 | P12: 1159795 | Q12: 497686 | R12: 2161977 | S12: 141825 | T12: 34861 | U12: 110963 | V12: 333907 | W12: 1280192 | X12: 1721216
A13: 순외환손익 | B13: ='HD현대중공업(누적)'!B5+'HD현대중공업(누적)'!B7-'HD현대중공업(누적)'!B6-'HD현대중공업(누적)'!B8 | C13: ='HD현대중공업(누적)'!C5+'HD현대중공업(누적)'!C7-'HD현대중공업(누적)'!C6-'HD현대중공업(누적)'!C8 | D13: ='HD현대중공업(누적)'!D5+'HD현대중공업(누적)'!D7-'HD현대중공업(누적)'!D6-'HD현대중공업(누적)'!D8 | E13: ='HD현대중공업(누적)'!E5+'HD현대중공업(누적)'!E7-'HD현대중공업(누적)'!E6-'HD현대중공업(누적)'!E8 | F13: ='HD현대중공업(누적)'!F5+'HD현대중공업(누적)'!F7-'HD현대중공업(누적)'!F6-'HD현대중공업(누적)'!F8 | G13: ='HD현대중공업(누적)'!G5+'HD현대중공업(누적)'!G7-'HD현대중공업(누적)'!G6-'HD현대중공업(누적)'!G8 | H13: ='HD현대중공업(누적)'!H5+'HD현대중공업(누적)'!H7-'HD현대중공업(누적)'!H6-'HD현대중공업(누적)'!H8 | I13: ='HD현대중공업(누적)'!I5+'HD현대중공업(누적)'!I7-'HD현대중공업(누적)'!I6-'HD현대중공업(누적)'!I8 | ... X13: ='HD현대중공업(누적)'!X5+'HD현대중공업(누적)'!X7-'HD현대중공업(누적)'!X6-'HD현대중공업(누적)'!X8
A14: 순파생손익 | B14: ='HD현대중공업(누적)'!B9+'HD현대중공업(누적)'!B11-'HD현대중공업(누적)'!B10-'HD현대중공업(누적)'!B12 | C14: ='HD현대중공업(누적)'!C9+'HD현대중공업(누적)'!C11-'HD현대중공업(누적)'!C10-'HD현대중공업(누적)'!C12 | D14: ='HD현대중공업(누적)'!D9+'HD현대중공업(누적)'!D11-'HD현대중공업(누적)'!D10-'HD현대중공업(누적)'!D12 | E14: ='HD현대중공업(누적)'!E9+'HD현대중공업(누적)'!E11-'HD현대중공업(누적)'!E10-'HD현대중공업(누적)'!E12 | F14: ='HD현대중공업(누적)'!F9+'HD현대중공업(누적)'!F11-'HD현대중공업(누적)'!F10-'HD현대중공업(누적)'!F12 | G14: ='HD현대중공업(누적)'!G9+'HD현대중공업(누적)'!G11-'HD현대중공업(누적)'!G10-'HD현대중공업(누적)'!G12 | H14: ='HD현대중공업(누적)'!H9+'HD현대중공업(누적)'!H11-'HD현대중공업(누적)'!H10-'HD현대중공업(누적)'!H12 | I14: ='HD현대중공업(누적)'!I9+'HD현대중공업(누적)'!I11-'HD현대중공업(누적)'!I10-'HD현대중공업(누적)'!I12 | ... X14: ='HD현대중공업(누적)'!X9+'HD현대중공업(누적)'!X11-'HD현대중공업(누적)'!X10-'HD현대중공업(누적)'!X12
A15: 총 순손익 | B15: ='HD현대중공업(누적)'!B13+'HD현대중공업(누적)'!B14 | C15: ='HD현대중공업(누적)'!C13+'HD현대중공업(누적)'!C14 | D15: ='HD현대중공업(누적)'!D13+'HD현대중공업(누적)'!D14 | E15: ='HD현대중공업(누적)'!E13+'HD현대중공업(누적)'!E14 | F15: ='HD현대중공업(누적)'!F13+'HD현대중공업(누적)'!F14 | G15: ='HD현대중공업(누적)'!G13+'HD현대중공업(누적)'!G14 | H15: ='HD현대중공업(누적)'!H13+'HD현대중공업(누적)'!H14 | I15: ='HD현대중공업(누적)'!I13+'HD현대중공업(누적)'!I14 | ... X15: ='HD현대중공업(누적)'!X13+'HD현대중공업(누적)'!X14

Sheet HD현대중공업(분기)
A1: HD현대중공업 외환·파생손익 — 분기별(비누적)
A2: (단위: 백만원, 누적 차감 방식 — (누적) 시트 수식 참조. '~누적' 열은 이전 분기 보고서가 없어 누적값 그대로)
A4: 항목 | B4: 2020 ~4Q누적 | C4: 2021 1Q | D4: 2021 2Q | E4: 2021 3Q | F4: 2021 4Q | G4: 2022 1Q | H4: 2022 2Q | I4: 2022 3Q | J4: 2022 4Q | K4: 2023 1Q | L4: 2023 2Q | M4: 2023 3Q | N4: 2023 4Q | O4: 2024 1Q | P4: 2024 2Q | Q4: 2024 3Q | R4: 2024 4Q | S4: 2025 1Q | T4: 2025 2Q | U4: 2025 3Q | V4: 2025 4Q | W4: 2026 1Q | X4: 2026 2Q
A5: 외환차익 | B5: ='HD현대중공업(누적)'!B5 | C5: ='HD현대중공업(누적)'!C5 | D5: ='HD현대중공업(누적)'!D5-'HD현대중공업(누적)'!C5 | E5: ='HD현대중공업(누적)'!E5-'HD현대중공업(누적)'!D5 | F5: ='HD현대중공업(누적)'!F5-'HD현대중공업(누적)'!E5 | G5: ='HD현대중공업(누적)'!G5 | H5: ='HD현대중공업(누적)'!H5-'HD현대중공업(누적)'!G5 | I5: ='HD현대중공업(누적)'!I5-'HD현대중공업(누적)'!H5 | J5: ='HD현대중공업(누적)'!J5-'HD현대중공업(누적)'!I5 | K5: ='HD현대중공업(누적)'!K5 | L5: ='HD현대중공업(누적)'!L5-'HD현대중공업(누적)'!K5 | M5: ='HD현대중공업(누적)'!M5-'HD현대중공업(누적)'!L5 | N5: ='HD현대중공업(누적)'!N5-'HD현대중공업(누적)'!M5 | O5: ='HD현대중공업(누적)'!O5 | P5: ='HD현대중공업(누적)'!P5-'HD현대중공업(누적)'!O5 | Q5: ='HD현대중공업(누적)'!Q5-'HD현대중공업(누적)'!P5 | R5: ='HD현대중공업(누적)'!R5-'HD현대중공업(누적)'!Q5 | S5: ='HD현대중공업(누적)'!S5 | T5: ='HD현대중공업(누적)'!T5-'HD현대중공업(누적)'!S5 | U5: ='HD현대중공업(누적)'!U5-'HD현대중공업(누적)'!T5 | V5: ='HD현대중공업(누적)'!V5-'HD현대중공업(누적)'!U5 | W5: ='HD현대중공업(누적)'!W5 | X5: ='HD현대중공업(누적)'!X5-'HD현대중공업(누적)'!W5
A6: 외환차손 | B6: ='HD현대중공업(누적)'!B6 | C6: ='HD현대중공업(누적)'!C6 | D6: ='HD현대중공업(누적)'!D6-'HD현대중공업(누적)'!C6 | E6: ='HD현대중공업(누적)'!E6-'HD현대중공업(누적)'!D6 | F6: ='HD현대중공업(누적)'!F6-'HD현대중공업(누적)'!E6 | G6: ='HD현대중공업(누적)'!G6 | H6: ='HD현대중공업(누적)'!H6-'HD현대중공업(누적)'!G6 | I6: ='HD현대중공업(누적)'!I6-'HD현대중공업(누적)'!H6 | J6: ='HD현대중공업(누적)'!J6-'HD현대중공업(누적)'!I6 | K6: ='HD현대중공업(누적)'!K6 | L6: ='HD현대중공업(누적)'!L6-'HD현대중공업(누적)'!K6 | M6: ='HD현대중공업(누적)'!M6-'HD현대중공업(누적)'!L6 | N6: ='HD현대중공업(누적)'!N6-'HD현대중공업(누적)'!M6 | O6: ='HD현대중공업(누적)'!O6 | P6: ='HD현대중공업(누적)'!P6-'HD현대중공업(누적)'!O6 | Q6: ='HD현대중공업(누적)'!Q6-'HD현대중공업(누적)'!P6 | R6: ='HD현대중공업(누적)'!R6-'HD현대중공업(누적)'!Q6 | S6: ='HD현대중공업(누적)'!S6 | T6: ='HD현대중공업(누적)'!T6-'HD현대중공업(누적)'!S6 | U6: ='HD현대중공업(누적)'!U6-'HD현대중공업(누적)'!T6 | V6: ='HD현대중공업(누적)'!V6-'HD현대중공업(누적)'!U6 | W6: ='HD현대중공업(누적)'!W6 | X6: ='HD현대중공업(누적)'!X6-'HD현대중공업(누적)'!W6
A7: 외화환산이익 | B7: ='HD현대중공업(누적)'!B7 | C7: ='HD현대중공업(누적)'!C7 | D7: ='HD현대중공업(누적)'!D7-'HD현대중공업(누적)'!C7 | E7: ='HD현대중공업(누적)'!E7-'HD현대중공업(누적)'!D7 | F7: ='HD현대중공업(누적)'!F7-'HD현대중공업(누적)'!E7 | G7: ='HD현대중공업(누적)'!G7 | H7: ='HD현대중공업(누적)'!H7-'HD현대중공업(누적)'!G7 | I7: ='HD현대중공업(누적)'!I7-'HD현대중공업(누적)'!H7 | J7: ='HD현대중공업(누적)'!J7-'HD현대중공업(누적)'!I7 | K7: ='HD현대중공업(누적)'!K7 | L7: ='HD현대중공업(누적)'!L7-'HD현대중공업(누적)'!K7 | M7: ='HD현대중공업(누적)'!M7-'HD현대중공업(누적)'!L7 | N7: ='HD현대중공업(누적)'!N7-'HD현대중공업(누적)'!M7 | O7: ='HD현대중공업(누적)'!O7 | P7: ='HD현대중공업(누적)'!P7-'HD현대중공업(누적)'!O7 | Q7: ='HD현대중공업(누적)'!Q7-'HD현대중공업(누적)'!P7 | R7: ='HD현대중공업(누적)'!R7-'HD현대중공업(누적)'!Q7 | S7: ='HD현대중공업(누적)'!S7 | T7: ='HD현대중공업(누적)'!T7-'HD현대중공업(누적)'!S7 | U7: ='HD현대중공업(누적)'!U7-'HD현대중공업(누적)'!T7 | V7: ='HD현대중공업(누적)'!V7-'HD현대중공업(누적)'!U7 | W7: ='HD현대중공업(누적)'!W7 | X7: ='HD현대중공업(누적)'!X7-'HD현대중공업(누적)'!W7
A8: 외화환산손실 | B8: ='HD현대중공업(누적)'!B8 | C8: ='HD현대중공업(누적)'!C8 | D8: ='HD현대중공업(누적)'!D8-'HD현대중공업(누적)'!C8 | E8: ='HD현대중공업(누적)'!E8-'HD현대중공업(누적)'!D8 | F8: ='HD현대중공업(누적)'!F8-'HD현대중공업(누적)'!E8 | G8: ='HD현대중공업(누적)'!G8 | H8: ='HD현대중공업(누적)'!H8-'HD현대중공업(누적)'!G8 | I8: ='HD현대중공업(누적)'!I8-'HD현대중공업(누적)'!H8 | J8: ='HD현대중공업(누적)'!J8-'HD현대중공업(누적)'!I8 | K8: ='HD현대중공업(누적)'!K8 | L8: ='HD현대중공업(누적)'!L8-'HD현대중공업(누적)'!K8 | M8: ='HD현대중공업(누적)'!M8-'HD현대중공업(누적)'!L8 | N8: ='HD현대중공업(누적)'!N8-'HD현대중공업(누적)'!M8 | O8: ='HD현대중공업(누적)'!O8 | P8: ='HD현대중공업(누적)'!P8-'HD현대중공업(누적)'!O8 | Q8: ='HD현대중공업(누적)'!Q8-'HD현대중공업(누적)'!P8 | R8: ='HD현대중공업(누적)'!R8-'HD현대중공업(누적)'!Q8 | S8: ='HD현대중공업(누적)'!S8 | T8: ='HD현대중공업(누적)'!T8-'HD현대중공업(누적)'!S8 | U8: ='HD현대중공업(누적)'!U8-'HD현대중공업(누적)'!T8 | V8: ='HD현대중공업(누적)'!V8-'HD현대중공업(누적)'!U8 | W8: ='HD현대중공업(누적)'!W8 | X8: ='HD현대중공업(누적)'!X8-'HD현대중공업(누적)'!W8
A9: 파생거래이익 | B9: ='HD현대중공업(누적)'!B9 | C9: ='HD현대중공업(누적)'!C9 | D9: ='HD현대중공업(누적)'!D9-'HD현대중공업(누적)'!C9 | E9: ='HD현대중공업(누적)'!E9-'HD현대중공업(누적)'!D9 | F9: ='HD현대중공업(누적)'!F9-'HD현대중공업(누적)'!E9 | G9: ='HD현대중공업(누적)'!G9 | H9: ='HD현대중공업(누적)'!H9-'HD현대중공업(누적)'!G9 | I9: ='HD현대중공업(누적)'!I9-'HD현대중공업(누적)'!H9 | J9: ='HD현대중공업(누적)'!J9-'HD현대중공업(누적)'!I9 | K9: ='HD현대중공업(누적)'!K9 | L9: ='HD현대중공업(누적)'!L9-'HD현대중공업(누적)'!K9 | M9: ='HD현대중공업(누적)'!M9-'HD현대중공업(누적)'!L9 | N9: ='HD현대중공업(누적)'!N9-'HD현대중공업(누적)'!M9 | O9: ='HD현대중공업(누적)'!O9 | P9: ='HD현대중공업(누적)'!P9-'HD현대중공업(누적)'!O9 | Q9: ='HD현대중공업(누적)'!Q9-'HD현대중공업(누적)'!P9 | R9: ='HD현대중공업(누적)'!R9-'HD현대중공업(누적)'!Q9 | S9: ='HD현대중공업(누적)'!S9 | T9: ='HD현대중공업(누적)'!T9-'HD현대중공업(누적)'!S9 | U9: ='HD현대중공업(누적)'!U9-'HD현대중공업(누적)'!T9 | V9: ='HD현대중공업(누적)'!V9-'HD현대중공업(누적)'!U9 | W9: ='HD현대중공업(누적)'!W9 | X9: ='HD현대중공업(누적)'!X9-'HD현대중공업(누적)'!W9
A10: 파생거래손실 | B10: ='HD현대중공업(누적)'!B10 | C10: ='HD현대중공업(누적)'!C10 | D10: ='HD현대중공업(누적)'!D10-'HD현대중공업(누적)'!C10 | E10: ='HD현대중공업(누적)'!E10-'HD현대중공업(누적)'!D10 | F10: ='HD현대중공업(누적)'!F10-'HD현대중공업(누적)'!E10 | G10: ='HD현대중공업(누적)'!G10 | H10: ='HD현대중공업(누적)'!H10-'HD현대중공업(누적)'!G10 | I10: ='HD현대중공업(누적)'!I10-'HD현대중공업(누적)'!H10 | J10: ='HD현대중공업(누적)'!J10-'HD현대중공업(누적)'!I10 | K10: ='HD현대중공업(누적)'!K10 | L10: ='HD현대중공업(누적)'!L10-'HD현대중공업(누적)'!K10 | M10: ='HD현대중공업(누적)'!M10-'HD현대중공업(누적)'!L10 | N10: ='HD현대중공업(누적)'!N10-'HD현대중공업(누적)'!M10 | O10: ='HD현대중공업(누적)'!O10 | P10: ='HD현대중공업(누적)'!P10-'HD현대중공업(누적)'!O10 | Q10: ='HD현대중공업(누적)'!Q10-'HD현대중공업(누적)'!P10 | R10: ='HD현대중공업(누적)'!R10-'HD현대중공업(누적)'!Q10 | S10: ='HD현대중공업(누적)'!S10 | T10: ='HD현대중공업(누적)'!T10-'HD현대중공업(누적)'!S10 | U10: ='HD현대중공업(누적)'!U10-'HD현대중공업(누적)'!T10 | V10: ='HD현대중공업(누적)'!V10-'HD현대중공업(누적)'!U10 | W10: ='HD현대중공업(누적)'!W10 | X10: ='HD현대중공업(누적)'!X10-'HD현대중공업(누적)'!W10
A11: 파생평가이익 | B11: ='HD현대중공업(누적)'!B11 | C11: ='HD현대중공업(누적)'!C11 | D11: ='HD현대중공업(누적)'!D11-'HD현대중공업(누적)'!C11 | E11: ='HD현대중공업(누적)'!E11-'HD현대중공업(누적)'!D11 | F11: ='HD현대중공업(누적)'!F11-'HD현대중공업(누적)'!E11 | G11: ='HD현대중공업(누적)'!G11 | H11: ='HD현대중공업(누적)'!H11-'HD현대중공업(누적)'!G11 | I11: ='HD현대중공업(누적)'!I11-'HD현대중공업(누적)'!H11 | J11: ='HD현대중공업(누적)'!J11-'HD현대중공업(누적)'!I11 | K11: ='HD현대중공업(누적)'!K11 | L11: ='HD현대중공업(누적)'!L11-'HD현대중공업(누적)'!K11 | M11: ='HD현대중공업(누적)'!M11-'HD현대중공업(누적)'!L11 | N11: ='HD현대중공업(누적)'!N11-'HD현대중공업(누적)'!M11 | O11: ='HD현대중공업(누적)'!O11 | P11: ='HD현대중공업(누적)'!P11-'HD현대중공업(누적)'!O11 | Q11: ='HD현대중공업(누적)'!Q11-'HD현대중공업(누적)'!P11 | R11: ='HD현대중공업(누적)'!R11-'HD현대중공업(누적)'!Q11 | S11: ='HD현대중공업(누적)'!S11 | T11: ='HD현대중공업(누적)'!T11-'HD현대중공업(누적)'!S11 | U11: ='HD현대중공업(누적)'!U11-'HD현대중공업(누적)'!T11 | V11: ='HD현대중공업(누적)'!V11-'HD현대중공업(누적)'!U11 | W11: ='HD현대중공업(누적)'!W11 | X11: ='HD현대중공업(누적)'!X11-'HD현대중공업(누적)'!W11
A12: 파생평가손실 | B12: ='HD현대중공업(누적)'!B12 | C12: ='HD현대중공업(누적)'!C12 | D12: ='HD현대중공업(누적)'!D12-'HD현대중공업(누적)'!C12 | E12: ='HD현대중공업(누적)'!E12-'HD현대중공업(누적)'!D12 | F12: ='HD현대중공업(누적)'!F12-'HD현대중공업(누적)'!E12 | G12: ='HD현대중공업(누적)'!G12 | H12: ='HD현대중공업(누적)'!H12-'HD현대중공업(누적)'!G12 | I12: ='HD현대중공업(누적)'!I12-'HD현대중공업(누적)'!H12 | J12: ='HD현대중공업(누적)'!J12-'HD현대중공업(누적)'!I12 | K12: ='HD현대중공업(누적)'!K12 | L12: ='HD현대중공업(누적)'!L12-'HD현대중공업(누적)'!K12 | M12: ='HD현대중공업(누적)'!M12-'HD현대중공업(누적)'!L12 | N12: ='HD현대중공업(누적)'!N12-'HD현대중공업(누적)'!M12 | O12: ='HD현대중공업(누적)'!O12 | P12: ='HD현대중공업(누적)'!P12-'HD현대중공업(누적)'!O12 | Q12: ='HD현대중공업(누적)'!Q12-'HD현대중공업(누적)'!P12 | R12: ='HD현대중공업(누적)'!R12-'HD현대중공업(누적)'!Q12 | S12: ='HD현대중공업(누적)'!S12 | T12: ='HD현대중공업(누적)'!T12-'HD현대중공업(누적)'!S12 | U12: ='HD현대중공업(누적)'!U12-'HD현대중공업(누적)'!T12 | V12: ='HD현대중공업(누적)'!V12-'HD현대중공업(누적)'!U12 | W12: ='HD현대중공업(누적)'!W12 | X12: ='HD현대중공업(누적)'!X12-'HD현대중공업(누적)'!W12
A13: 순외환손익 | B13: ='HD현대중공업(누적)'!B13 | C13: ='HD현대중공업(누적)'!C13 | D13: ='HD현대중공업(누적)'!D13-'HD현대중공업(누적)'!C13 | E13: ='HD현대중공업(누적)'!E13-'HD현대중공업(누적)'!D13 | F13: ='HD현대중공업(누적)'!F13-'HD현대중공업(누적)'!E13 | G13: ='HD현대중공업(누적)'!G13 | H13: ='HD현대중공업(누적)'!H13-'HD현대중공업(누적)'!G13 | I13: ='HD현대중공업(누적)'!I13-'HD현대중공업(누적)'!H13 | J13: ='HD현대중공업(누적)'!J13-'HD현대중공업(누적)'!I13 | K13: ='HD현대중공업(누적)'!K13 | L13: ='HD현대중공업(누적)'!L13-'HD현대중공업(누적)'!K13 | M13: ='HD현대중공업(누적)'!M13-'HD현대중공업(누적)'!L13 | N13: ='HD현대중공업(누적)'!N13-'HD현대중공업(누적)'!M13 | O13: ='HD현대중공업(누적)'!O13 | P13: ='HD현대중공업(누적)'!P13-'HD현대중공업(누적)'!O13 | Q13: ='HD현대중공업(누적)'!Q13-'HD현대중공업(누적)'!P13 | R13: ='HD현대중공업(누적)'!R13-'HD현대중공업(누적)'!Q13 | S13: ='HD현대중공업(누적)'!S13 | T13: ='HD현대중공업(누적)'!T13-'HD현대중공업(누적)'!S13 | U13: ='HD현대중공업(누적)'!U13-'HD현대중공업(누적)'!T13 | V13: ='HD현대중공업(누적)'!V13-'HD현대중공업(누적)'!U13 | W13: ='HD현대중공업(누적)'!W13 | X13: ='HD현대중공업(누적)'!X13-'HD현대중공업(누적)'!W13
A14: 순파생손익 | B14: ='HD현대중공업(누적)'!B14 | C14: ='HD현대중공업(누적)'!C14 | D14: ='HD현대중공업(누적)'!D14-'HD현대중공업(누적)'!C14 | E14: ='HD현대중공업(누적)'!E14-'HD현대중공업(누적)'!D14 | F14: ='HD현대중공업(누적)'!F14-'HD현대중공업(누적)'!E14 | G14: ='HD현대중공업(누적)'!G14 | H14: ='HD현대중공업(누적)'!H14-'HD현대중공업(누적)'!G14 | I14: ='HD현대중공업(누적)'!I14-'HD현대중공업(누적)'!H14 | J14: ='HD현대중공업(누적)'!J14-'HD현대중공업(누적)'!I14 | K14: ='HD현대중공업(누적)'!K14 | L14: ='HD현대중공업(누적)'!L14-'HD현대중공업(누적)'!K14 | M14: ='HD현대중공업(누적)'!M14-'HD현대중공업(누적)'!L14 | N14: ='HD현대중공업(누적)'!N14-'HD현대중공업(누적)'!M14 | O14: ='HD현대중공업(누적)'!O14 | P14: ='HD현대중공업(누적)'!P14-'HD현대중공업(누적)'!O14 | Q14: ='HD현대중공업(누적)'!Q14-'HD현대중공업(누적)'!P14 | R14: ='HD현대중공업(누적)'!R14-'HD현대중공업(누적)'!Q14 | S14: ='HD현대중공업(누적)'!S14 | T14: ='HD현대중공업(누적)'!T14-'HD현대중공업(누적)'!S14 | U14: ='HD현대중공업(누적)'!U14-'HD현대중공업(누적)'!T14 | V14: ='HD현대중공업(누적)'!V14-'HD현대중공업(누적)'!U14 | W14: ='HD현대중공업(누적)'!W14 | X14: ='HD현대중공업(누적)'!X14-'HD현대중공업(누적)'!W14
A15: 총 순손익 | B15: ='HD현대중공업(누적)'!B15 | C15: ='HD현대중공업(누적)'!C15 | D15: ='HD현대중공업(누적)'!D15-'HD현대중공업(누적)'!C15 | E15: ='HD현대중공업(누적)'!E15-'HD현대중공업(누적)'!D15 | F15: ='HD현대중공업(누적)'!F15-'HD현대중공업(누적)'!E15 | G15: ='HD현대중공업(누적)'!G15 | H15: ='HD현대중공업(누적)'!H15-'HD현대중공업(누적)'!G15 | I15: ='HD현대중공업(누적)'!I15-'HD현대중공업(누적)'!H15 | J15: ='HD현대중공업(누적)'!J15-'HD현대중공업(누적)'!I15 | K15: ='HD현대중공업(누적)'!K15 | L15: ='HD현대중공업(누적)'!L15-'HD현대중공업(누적)'!K15 | M15: ='HD현대중공업(누적)'!M15-'HD현대중공업(누적)'!L15 | N15: ='HD현대중공업(누적)'!N15-'HD현대중공업(누적)'!M15 | O15: ='HD현대중공업(누적)'!O15 | P15: ='HD현대중공업(누적)'!P15-'HD현대중공업(누적)'!O15 | Q15: ='HD현대중공업(누적)'!Q15-'HD현대중공업(누적)'!P15 | R15: ='HD현대중공업(누적)'!R15-'HD현대중공업(누적)'!Q15 | S15: ='HD현대중공업(누적)'!S15 | T15: ='HD현대중공업(누적)'!T15-'HD현대중공업(누적)'!S15 | U15: ='HD현대중공업(누적)'!U15-'HD현대중공업(누적)'!T15 | V15: ='HD현대중공업(누적)'!V15-'HD현대중공업(누적)'!U15 | W15: ='HD현대중공업(누적)'!W15 | X15: ='HD현대중공업(누적)'!X15-'HD현대중공업(누적)'!W15

Sheet 삼성중공업(누적)
A1: 삼성중공업 외환·파생손익 — 보고서 누적치
A2: (단위: 백만원, 각 열은 해당 보고서의 당기 누적. *=별도 기준)
A4: 항목 | B4: 2016.09 | C4: 2016.12 | D4: 2017.03 | E4: 2017.06 | F4: 2017.09 | G4: 2017.12 | H4: 2018.03 | I4: 2018.06 | J4: 2018.09 | K4: 2018.12 | L4: 2019.03 | M4: 2019.06 | N4: 2019.09 | O4: 2019.12 | P4: 2020.03 | Q4: 2020.06 | R4: 2020.09 | S4: 2020.12 | T4: 2021.03 | U4: 2021.06 | V4: 2021.09 | W4: 2021.12 | X4: 2022.03 | Y4: 2022.06 | Z4: 2022.09 | AA4: 2022.12 | AB4: 2023.03 | AC4: 2023.06 | AD4: 2023.09 | AE4: 2023.12 | AF4: 2024.03 | AG4: 2024.06 | AH4: 2024.09 | AI4: 2024.12 | AJ4: 2025.03 | AK4: 2025.06 | AL4: 2025.09 | AM4: 2025.12 | AN4: 2026.03 | AO4: 2026.06
A5: 외환차익 | B5: 139253 | C5: 141919 | D5: 33808 | E5: 40516 | F5: 49456 | G5: 60271 | H5: 24039 | I5: 40066 | J5: 70591 | K5: 90592 | L5: 11815 | M5: 29941 | N5: 88744 | O5: 118318 | P5: 53880 | Q5: 157584 | R5: 190015 | S5: 233979 | T5: 56087 | U5: 98401 | V5: 139190 | W5: 165929 | X5: 21097 | Y5: 102732 | Z5: 125426 | AA5: 173727 | AB5: 72035 | AC5: 108347 | AD5: 134432 | AE5: 12976 | AF5: 64439 | AG5: 135697 | AH5: 211435 | AI5: 315929 | AJ5: 29819 | AK5: 77160 | AL5: 97445 | AM5: 144099 | AN5: 138902 | AO5: 208999
A6: 외환차손 | B6: 74435 | C6: 82752 | D6: 98344 | E6: 190346 | F6: 247342 | G6: 255006 | H6: 21539 | I6: 31129 | J6: 48462 | K6: 59705 | L6: 4958 | M6: 13642 | N6: 42225 | O6: 67925 | P6: 38438 | Q6: 95464 | R6: 107662 | S6: 142317 | T6: 51620 | U6: 82850 | V6: 102933 | W6: 115535 | X6: 13711 | Y6: 53368 | Z6: 83195 | AA6: 124059 | AB6: 70234 | AC6: 84541 | AD6: 102094 | AE6: 29388 | AF6: 40578 | AG6: 67595 | AH6: 98551 | AI6: 175760 | AJ6: 51021 | AK6: 146337 | AL6: 208265 | AM6: 257645 | AN6: 82712 | AO6: 127451
A7: 외화환산이익 | B7: 65851 | C7: 129350 | D7: 56578 | E7: 44644 | F7: 32820 | G7: 49061 | H7: 24495 | I7: 102806 | J7: 57095 | K7: 36811 | L7: 41876 | M7: 72929 | N7: 126368 | O7: 92711 | P7: 136979 | Q7: 64601 | R7: 21157 | S7: 32264 | T7: 70705 | U7: 38102 | V7: 49284 | W7: 29540 | X7: 27170 | Y7: 45954 | Z7: 90000 | AA7: 34327 | AB7: 51999 | AC7: 48141 | AD7: 44898 | AE7: 20390 | AF7: 119647 | AG7: 154072 | AH7: 29647 | AI7: 89483 | AJ7: 5971 | AK7: 39755 | AL7: 28637 | AM7: 41895 | AN7: 68405 | AO7: 47186
A8: 외화환산손실 | B8: 292354 | C8: 77524 | D8: 350408 | E8: 199679 | F8: 139936 | G8: 252104 | H8: 36351 | I8: 61938 | J8: 30136 | K8: 33812 | L8: 16759 | M8: 31795 | N8: 70429 | O8: 75080 | P8: 53593 | Q8: 34835 | R8: 15838 | S8: 40004 | T8: 19134 | U8: 12965 | V8: 29557 | W8: 23630 | X8: 9454 | Y8: 25936 | Z8: 63762 | AA8: 31711 | AB8: 4843 | AC8: 17426 | AD8: 23121 | AE8: 10891 | AF8: 14613 | AG8: 30177 | AH8: 13117 | AI8: 52577 | AJ8: 12258 | AK8: 126531 | AL8: 48818 | AM8: 51748 | AN8: 23094 | AO8: 25845
A9: 파생거래이익 | B9: 357023 | C9: 432947 | D9: 383983 | E9: 616424 | F9: 720108 | G9: 828391 | H9: 17258 | I9: 34388 | J9: 86552 | K9: 137675 | L9: 14264 | M9: 175619 | N9: 195208 | O9: 327057 | P9: 4663 | Q9: 21545 | R9: 63744 | S9: 219686 | T9: 3176 | U9: 24606 | V9: 25772 | W9: 32338 | X9: 7026 | Y9: 11079 | Z9: 11262 | AA9: 68006 | AB9: 85921 | AC9: 95930 | AD9: 123164 | AE9: 0 | AF9: 2753 | AG9: 5610 | AH9: 34434 | AI9: 35782 | AJ9: 78407 | AK9: 316928 | AL9: 523655 | AM9: 536164 | AN9: 4707 | AO9: 7701
A10: 파생거래손실 | B10: 182262 | C10: 291843 | D10: 63473 | E10: 141372 | F10: 231894 | G10: 268913 | H10: 15236 | I10: 58377 | J10: 228548 | K10: 337074 | L10: 31798 | M10: 233600 | N10: 252052 | O10: 478274 | P10: 131602 | Q10: 239808 | R10: 291137 | S10: 294814 | T10: 95816 | U10: 147497 | V10: 266744 | W10: 409896 | X10: 83534 | Y10: 327933 | Z10: 694243 | AA10: 1192028 | AB10: 139775 | AC10: 352736 | AD10: 538798 | AE10: 0 | AF10: 351377 | AG10: 828707 | AH10: 1090103 | AI10: 1438242 | AJ10: 18738 | AK10: 43646 | AL10: 64711 | AM10: 154655 | AN10: 92601 | AO10: 230678
A11: 파생평가이익 | B11: 746326 | C11: 135900 | D11: 569227 | E11: 225626 | F11: 165987 | G11: 522477 | H11: 91341 | I11: 132541 | J11: 120824 | K11: 104052 | L11: 96727 | M11: 171726 | N11: 229420 | O11: 251282 | P11: 1241 | Q11: 13509 | R11: 21065 | S11: 402311 | T11: 5 | U11: 325 | V11: 107 | W11: 3116 | X11: 29620 | Y11: 1481 | Z11: 107 | AA11: 541770 | AB11: 3540 | AC11: 28250 | AD11: 442 | AE11: 148767 | AF11: 0 | AG11: 112 | AH11: 212990 | AI11: 570189 | AJ11: 721111 | AK11: 205935 | AL11: 386704 | AM11: 60376 | AN11: 839435 | AO11: 877936
A12: 파생평가손실 | B12: 242377 | C12: 466414 | D12: 232355 | E12: 173533 | F12: 151049 | G12: 228338 | H12: 63663 | I12: 395521 | J12: 243553 | K12: 254489 | L12: 283459 | M12: 480208 | N12: 816805 | O12: 432176 | P12: 660635 | Q12: 460647 | R12: 235763 | S12: 1276 | T12: 385617 | U12: 351667 | V12: 905148 | W12: 783569 | X12: 205731 | Y12: 1254028 | Z12: 3352985 | AA12: 673149 | AB12: 661235 | AC12: 747757 | AD12: 1501652 | AE12: 461420 | AF12: 1010404 | AG12: 1606709 | AH12: 394422 | AI12: 3002943 | AJ12: 214629 | AK12: 834 | AL12: 134519 | AM12: 488894 | AN12: 1485842 | AO12: 1933823
A13: 순외환손익 | B13: ='삼성중공업(누적)'!B5+'삼성중공업(누적)'!B7-'삼성중공업(누적)'!B6-'삼성중공업(누적)'!B8 | C13: ='삼성중공업(누적)'!C5+'삼성중공업(누적)'!C7-'삼성중공업(누적)'!C6-'삼성중공업(누적)'!C8 | D13: ='삼성중공업(누적)'!D5+'삼성중공업(누적)'!D7-'삼성중공업(누적)'!D6-'삼성중공업(누적)'!D8 | E13: ='삼성중공업(누적)'!E5+'삼성중공업(누적)'!E7-'삼성중공업(누적)'!E6-'삼성중공업(누적)'!E8 | F13: ='삼성중공업(누적)'!F5+'삼성중공업(누적)'!F7-'삼성중공업(누적)'!F6-'삼성중공업(누적)'!F8 | G13: ='삼성중공업(누적)'!G5+'삼성중공업(누적)'!G7-'삼성중공업(누적)'!G6-'삼성중공업(누적)'!G8 | H13: ='삼성중공업(누적)'!H5+'삼성중공업(누적)'!H7-'삼성중공업(누적)'!H6-'삼성중공업(누적)'!H8 | I13: ='삼성중공업(누적)'!I5+'삼성중공업(누적)'!I7-'삼성중공업(누적)'!I6-'삼성중공업(누적)'!I8 | ... AO13: ='삼성중공업(누적)'!AO5+'삼성중공업(누적)'!AO7-'삼성중공업(누적)'!AO6-'삼성중공업(누적)'!AO8
A14: 순파생손익 | B14: ='삼성중공업(누적)'!B9+'삼성중공업(누적)'!B11-'삼성중공업(누적)'!B10-'삼성중공업(누적)'!B12 | C14: ='삼성중공업(누적)'!C9+'삼성중공업(누적)'!C11-'삼성중공업(누적)'!C10-'삼성중공업(누적)'!C12 | D14: ='삼성중공업(누적)'!D9+'삼성중공업(누적)'!D11-'삼성중공업(누적)'!D10-'삼성중공업(누적)'!D12 | E14: ='삼성중공업(누적)'!E9+'삼성중공업(누적)'!E11-'삼성중공업(누적)'!E10-'삼성중공업(누적)'!E12 | F14: ='삼성중공업(누적)'!F9+'삼성중공업(누적)'!F11-'삼성중공업(누적)'!F10-'삼성중공업(누적)'!F12 | G14: ='삼성중공업(누적)'!G9+'삼성중공업(누적)'!G11-'삼성중공업(누적)'!G10-'삼성중공업(누적)'!G12 | H14: ='삼성중공업(누적)'!H9+'삼성중공업(누적)'!H11-'삼성중공업(누적)'!H10-'삼성중공업(누적)'!H12 | I14: ='삼성중공업(누적)'!I9+'삼성중공업(누적)'!I11-'삼성중공업(누적)'!I10-'삼성중공업(누적)'!I12 | ... AO14: ='삼성중공업(누적)'!AO9+'삼성중공업(누적)'!AO11-'삼성중공업(누적)'!AO10-'삼성중공업(누적)'!AO12
A15: 총 순손익 | B15: ='삼성중공업(누적)'!B13+'삼성중공업(누적)'!B14 | C15: ='삼성중공업(누적)'!C13+'삼성중공업(누적)'!C14 | D15: ='삼성중공업(누적)'!D13+'삼성중공업(누적)'!D14 | E15: ='삼성중공업(누적)'!E13+'삼성중공업(누적)'!E14 | F15: ='삼성중공업(누적)'!F13+'삼성중공업(누적)'!F14 | G15: ='삼성중공업(누적)'!G13+'삼성중공업(누적)'!G14 | H15: ='삼성중공업(누적)'!H13+'삼성중공업(누적)'!H14 | I15: ='삼성중공업(누적)'!I13+'삼성중공업(누적)'!I14 | ... AO15: ='삼성중공업(누적)'!AO13+'삼성중공업(누적)'!AO14

Sheet 삼성중공업(분기)
A1: 삼성중공업 외환·파생손익 — 분기별(비누적)
A2: (단위: 백만원, 누적 차감 방식 — (누적) 시트 수식 참조. '~누적' 열은 이전 분기 보고서가 없어 누적값 그대로)
A4: 항목 | B4: 2016 ~3Q누적 | C4: 2016 4Q | D4: 2017 1Q | E4: 2017 2Q | F4: 2017 3Q | G4: 2017 4Q | H4: 2018 1Q | I4: 2018 2Q | J4: 2018 3Q | K4: 2018 4Q | L4: 2019 1Q | M4: 2019 2Q | N4: 2019 3Q | O4: 2019 4Q | P4: 2020 1Q | Q4: 2020 2Q | R4: 2020 3Q | S4: 2020 4Q | T4: 2021 1Q | U4: 2021 2Q | V4: 2021 3Q | W4: 2021 4Q | X4: 2022 1Q | Y4: 2022 2Q | Z4: 2022 3Q | AA4: 2022 4Q | AB4: 2023 1Q | AC4: 2023 2Q | AD4: 2023 3Q | AE4: 2023 4Q | AF4: 2024 1Q | AG4: 2024 2Q | AH4: 2024 3Q | AI4: 2024 4Q | AJ4: 2025 1Q | AK4: 2025 2Q | AL4: 2025 3Q | AM4: 2025 4Q | AN4: 2026 1Q | AO4: 2026 2Q
A5: 외환차익 | B5: ='삼성중공업(누적)'!B5 | C5: ='삼성중공업(누적)'!C5-'삼성중공업(누적)'!B5 | D5: ='삼성중공업(누적)'!D5 | E5: ='삼성중공업(누적)'!E5-'삼성중공업(누적)'!D5 | F5: ='삼성중공업(누적)'!F5-'삼성중공업(누적)'!E5 | G5: ='삼성중공업(누적)'!G5-'삼성중공업(누적)'!F5 | H5: ='삼성중공업(누적)'!H5 | I5: ='삼성중공업(누적)'!I5-'삼성중공업(누적)'!H5 | J5: ='삼성중공업(누적)'!J5-'삼성중공업(누적)'!I5 | K5: ='삼성중공업(누적)'!K5-'삼성중공업(누적)'!J5 | L5: ='삼성중공업(누적)'!L5 | M5: ='삼성중공업(누적)'!M5-'삼성중공업(누적)'!L5 | N5: ='삼성중공업(누적)'!N5-'삼성중공업(누적)'!M5 | O5: ='삼성중공업(누적)'!O5-'삼성중공업(누적)'!N5 | P5: ='삼성중공업(누적)'!P5 | Q5: ='삼성중공업(누적)'!Q5-'삼성중공업(누적)'!P5 | R5: ='삼성중공업(누적)'!R5-'삼성중공업(누적)'!Q5 | S5: ='삼성중공업(누적)'!S5-'삼성중공업(누적)'!R5 | T5: ='삼성중공업(누적)'!T5 | U5: ='삼성중공업(누적)'!U5-'삼성중공업(누적)'!T5 | V5: ='삼성중공업(누적)'!V5-'삼성중공업(누적)'!U5 | W5: ='삼성중공업(누적)'!W5-'삼성중공업(누적)'!V5 | X5: ='삼성중공업(누적)'!X5 | Y5: ='삼성중공업(누적)'!Y5-'삼성중공업(누적)'!X5 | Z5: ='삼성중공업(누적)'!Z5-'삼성중공업(누적)'!Y5 | AA5: ='삼성중공업(누적)'!AA5-'삼성중공업(누적)'!Z5 | AB5: ='삼성중공업(누적)'!AB5 | AC5: ='삼성중공업(누적)'!AC5-'삼성중공업(누적)'!AB5 | AD5: ='삼성중공업(누적)'!AD5-'삼성중공업(누적)'!AC5 | AE5: ='삼성중공업(누적)'!AE5-'삼성중공업(누적)'!AD5 | AF5: ='삼성중공업(누적)'!AF5 | AG5: ='삼성중공업(누적)'!AG5-'삼성중공업(누적)'!AF5 | AH5: ='삼성중공업(누적)'!AH5-'삼성중공업(누적)'!AG5 | AI5: ='삼성중공업(누적)'!AI5-'삼성중공업(누적)'!AH5 | AJ5: ='삼성중공업(누적)'!AJ5 | AK5: ='삼성중공업(누적)'!AK5-'삼성중공업(누적)'!AJ5 | AL5: ='삼성중공업(누적)'!AL5-'삼성중공업(누적)'!AK5 | AM5: ='삼성중공업(누적)'!AM5-'삼성중공업(누적)'!AL5 | AN5: ='삼성중공업(누적)'!AN5 | AO5: ='삼성중공업(누적)'!AO5-'삼성중공업(누적)'!AN5
A6: 외환차손 | B6: ='삼성중공업(누적)'!B6 | C6: ='삼성중공업(누적)'!C6-'삼성중공업(누적)'!B6 | D6: ='삼성중공업(누적)'!D6 | E6: ='삼성중공업(누적)'!E6-'삼성중공업(누적)'!D6 | F6: ='삼성중공업(누적)'!F6-'삼성중공업(누적)'!E6 | G6: ='삼성중공업(누적)'!G6-'삼성중공업(누적)'!F6 | H6: ='삼성중공업(누적)'!H6 | I6: ='삼성중공업(누적)'!I6-'삼성중공업(누적)'!H6 | J6: ='삼성중공업(누적)'!J6-'삼성중공업(누적)'!I6 | K6: ='삼성중공업(누적)'!K6-'삼성중공업(누적)'!J6 | L6: ='삼성중공업(누적)'!L6 | M6: ='삼성중공업(누적)'!M6-'삼성중공업(누적)'!L6 | N6: ='삼성중공업(누적)'!N6-'삼성중공업(누적)'!M6 | O6: ='삼성중공업(누적)'!O6-'삼성중공업(누적)'!N6 | P6: ='삼성중공업(누적)'!P6 | Q6: ='삼성중공업(누적)'!Q6-'삼성중공업(누적)'!P6 | R6: ='삼성중공업(누적)'!R6-'삼성중공업(누적)'!Q6 | S6: ='삼성중공업(누적)'!S6-'삼성중공업(누적)'!R6 | T6: ='삼성중공업(누적)'!T6 | U6: ='삼성중공업(누적)'!U6-'삼성중공업(누적)'!T6 | V6: ='삼성중공업(누적)'!V6-'삼성중공업(누적)'!U6 | W6: ='삼성중공업(누적)'!W6-'삼성중공업(누적)'!V6 | X6: ='삼성중공업(누적)'!X6 | Y6: ='삼성중공업(누적)'!Y6-'삼성중공업(누적)'!X6 | Z6: ='삼성중공업(누적)'!Z6-'삼성중공업(누적)'!Y6 | AA6: ='삼성중공업(누적)'!AA6-'삼성중공업(누적)'!Z6 | AB6: ='삼성중공업(누적)'!AB6 | AC6: ='삼성중공업(누적)'!AC6-'삼성중공업(누적)'!AB6 | AD6: ='삼성중공업(누적)'!AD6-'삼성중공업(누적)'!AC6 | AE6: ='삼성중공업(누적)'!AE6-'삼성중공업(누적)'!AD6 | AF6: ='삼성중공업(누적)'!AF6 | AG6: ='삼성중공업(누적)'!AG6-'삼성중공업(누적)'!AF6 | AH6: ='삼성중공업(누적)'!AH6-'삼성중공업(누적)'!AG6 | AI6: ='삼성중공업(누적)'!AI6-'삼성중공업(누적)'!AH6 | AJ6: ='삼성중공업(누적)'!AJ6 | AK6: ='삼성중공업(누적)'!AK6-'삼성중공업(누적)'!AJ6 | AL6: ='삼성중공업(누적)'!AL6-'삼성중공업(누적)'!AK6 | AM6: ='삼성중공업(누적)'!AM6-'삼성중공업(누적)'!AL6 | AN6: ='삼성중공업(누적)'!AN6 | AO6: ='삼성중공업(누적)'!AO6-'삼성중공업(누적)'!AN6
A7: 외화환산이익 | B7: ='삼성중공업(누적)'!B7 | C7: ='삼성중공업(누적)'!C7-'삼성중공업(누적)'!B7 | D7: ='삼성중공업(누적)'!D7 | E7: ='삼성중공업(누적)'!E7-'삼성중공업(누적)'!D7 | F7: ='삼성중공업(누적)'!F7-'삼성중공업(누적)'!E7 | G7: ='삼성중공업(누적)'!G7-'삼성중공업(누적)'!F7 | H7: ='삼성중공업(누적)'!H7 | I7: ='삼성중공업(누적)'!I7-'삼성중공업(누적)'!H7 | J7: ='삼성중공업(누적)'!J7-'삼성중공업(누적)'!I7 | K7: ='삼성중공업(누적)'!K7-'삼성중공업(누적)'!J7 | L7: ='삼성중공업(누적)'!L7 | M7: ='삼성중공업(누적)'!M7-'삼성중공업(누적)'!L7 | N7: ='삼성중공업(누적)'!N7-'삼성중공업(누적)'!M7 | O7: ='삼성중공업(누적)'!O7-'삼성중공업(누적)'!N7 | P7: ='삼성중공업(누적)'!P7 | Q7: ='삼성중공업(누적)'!Q7-'삼성중공업(누적)'!P7 | R7: ='삼성중공업(누적)'!R7-'삼성중공업(누적)'!Q7 | S7: ='삼성중공업(누적)'!S7-'삼성중공업(누적)'!R7 | T7: ='삼성중공업(누적)'!T7 | U7: ='삼성중공업(누적)'!U7-'삼성중공업(누적)'!T7 | V7: ='삼성중공업(누적)'!V7-'삼성중공업(누적)'!U7 | W7: ='삼성중공업(누적)'!W7-'삼성중공업(누적)'!V7 | X7: ='삼성중공업(누적)'!X7 | Y7: ='삼성중공업(누적)'!Y7-'삼성중공업(누적)'!X7 | Z7: ='삼성중공업(누적)'!Z7-'삼성중공업(누적)'!Y7 | AA7: ='삼성중공업(누적)'!AA7-'삼성중공업(누적)'!Z7 | AB7: ='삼성중공업(누적)'!AB7 | AC7: ='삼성중공업(누적)'!AC7-'삼성중공업(누적)'!AB7 | AD7: ='삼성중공업(누적)'!AD7-'삼성중공업(누적)'!AC7 | AE7: ='삼성중공업(누적)'!AE7-'삼성중공업(누적)'!AD7 | AF7: ='삼성중공업(누적)'!AF7 | AG7: ='삼성중공업(누적)'!AG7-'삼성중공업(누적)'!AF7 | AH7: ='삼성중공업(누적)'!AH7-'삼성중공업(누적)'!AG7 | AI7: ='삼성중공업(누적)'!AI7-'삼성중공업(누적)'!AH7 | AJ7: ='삼성중공업(누적)'!AJ7 | AK7: ='삼성중공업(누적)'!AK7-'삼성중공업(누적)'!AJ7 | AL7: ='삼성중공업(누적)'!AL7-'삼성중공업(누적)'!AK7 | AM7: ='삼성중공업(누적)'!AM7-'삼성중공업(누적)'!AL7 | AN7: ='삼성중공업(누적)'!AN7 | AO7: ='삼성중공업(누적)'!AO7-'삼성중공업(누적)'!AN7
A8: 외화환산손실 | B8: ='삼성중공업(누적)'!B8 | C8: ='삼성중공업(누적)'!C8-'삼성중공업(누적)'!B8 | D8: ='삼성중공업(누적)'!D8 | E8: ='삼성중공업(누적)'!E8-'삼성중공업(누적)'!D8 | F8: ='삼성중공업(누적)'!F8-'삼성중공업(누적)'!E8 | G8: ='삼성중공업(누적)'!G8-'삼성중공업(누적)'!F8 | H8: ='삼성중공업(누적)'!H8 | I8: ='삼성중공업(누적)'!I8-'삼성중공업(누적)'!H8 | J8: ='삼성중공업(누적)'!J8-'삼성중공업(누적)'!I8 | K8: ='삼성중공업(누적)'!K8-'삼성중공업(누적)'!J8 | L8: ='삼성중공업(누적)'!L8 | M8: ='삼성중공업(누적)'!M8-'삼성중공업(누적)'!L8 | N8: ='삼성중공업(누적)'!N8-'삼성중공업(누적)'!M8 | O8: ='삼성중공업(누적)'!O8-'삼성중공업(누적)'!N8 | P8: ='삼성중공업(누적)'!P8 | Q8: ='삼성중공업(누적)'!Q8-'삼성중공업(누적)'!P8 | R8: ='삼성중공업(누적)'!R8-'삼성중공업(누적)'!Q8 | S8: ='삼성중공업(누적)'!S8-'삼성중공업(누적)'!R8 | T8: ='삼성중공업(누적)'!T8 | U8: ='삼성중공업(누적)'!U8-'삼성중공업(누적)'!T8 | V8: ='삼성중공업(누적)'!V8-'삼성중공업(누적)'!U8 | W8: ='삼성중공업(누적)'!W8-'삼성중공업(누적)'!V8 | X8: ='삼성중공업(누적)'!X8 | Y8: ='삼성중공업(누적)'!Y8-'삼성중공업(누적)'!X8 | Z8: ='삼성중공업(누적)'!Z8-'삼성중공업(누적)'!Y8 | AA8: ='삼성중공업(누적)'!AA8-'삼성중공업(누적)'!Z8 | AB8: ='삼성중공업(누적)'!AB8 | AC8: ='삼성중공업(누적)'!AC8-'삼성중공업(누적)'!AB8 | AD8: ='삼성중공업(누적)'!AD8-'삼성중공업(누적)'!AC8 | AE8: ='삼성중공업(누적)'!AE8-'삼성중공업(누적)'!AD8 | AF8: ='삼성중공업(누적)'!AF8 | AG8: ='삼성중공업(누적)'!AG8-'삼성중공업(누적)'!AF8 | AH8: ='삼성중공업(누적)'!AH8-'삼성중공업(누적)'!AG8 | AI8: ='삼성중공업(누적)'!AI8-'삼성중공업(누적)'!AH8 | AJ8: ='삼성중공업(누적)'!AJ8 | AK8: ='삼성중공업(누적)'!AK8-'삼성중공업(누적)'!AJ8 | AL8: ='삼성중공업(누적)'!AL8-'삼성중공업(누적)'!AK8 | AM8: ='삼성중공업(누적)'!AM8-'삼성중공업(누적)'!AL8 | AN8: ='삼성중공업(누적)'!AN8 | AO8: ='삼성중공업(누적)'!AO8-'삼성중공업(누적)'!AN8
A9: 파생거래이익 | B9: ='삼성중공업(누적)'!B9 | C9: ='삼성중공업(누적)'!C9-'삼성중공업(누적)'!B9 | D9: ='삼성중공업(누적)'!D9 | E9: ='삼성중공업(누적)'!E9-'삼성중공업(누적)'!D9 | F9: ='삼성중공업(누적)'!F9-'삼성중공업(누적)'!E9 | G9: ='삼성중공업(누적)'!G9-'삼성중공업(누적)'!F9 | H9: ='삼성중공업(누적)'!H9 | I9: ='삼성중공업(누적)'!I9-'삼성중공업(누적)'!H9 | J9: ='삼성중공업(누적)'!J9-'삼성중공업(누적)'!I9 | K9: ='삼성중공업(누적)'!K9-'삼성중공업(누적)'!J9 | L9: ='삼성중공업(누적)'!L9 | M9: ='삼성중공업(누적)'!M9-'삼성중공업(누적)'!L9 | N9: ='삼성중공업(누적)'!N9-'삼성중공업(누적)'!M9 | O9: ='삼성중공업(누적)'!O9-'삼성중공업(누적)'!N9 | P9: ='삼성중공업(누적)'!P9 | Q9: ='삼성중공업(누적)'!Q9-'삼성중공업(누적)'!P9 | R9: ='삼성중공업(누적)'!R9-'삼성중공업(누적)'!Q9 | S9: ='삼성중공업(누적)'!S9-'삼성중공업(누적)'!R9 | T9: ='삼성중공업(누적)'!T9 | U9: ='삼성중공업(누적)'!U9-'삼성중공업(누적)'!T9 | V9: ='삼성중공업(누적)'!V9-'삼성중공업(누적)'!U9 | W9: ='삼성중공업(누적)'!W9-'삼성중공업(누적)'!V9 | X9: ='삼성중공업(누적)'!X9 | Y9: ='삼성중공업(누적)'!Y9-'삼성중공업(누적)'!X9 | Z9: ='삼성중공업(누적)'!Z9-'삼성중공업(누적)'!Y9 | AA9: ='삼성중공업(누적)'!AA9-'삼성중공업(누적)'!Z9 | AB9: ='삼성중공업(누적)'!AB9 | AC9: ='삼성중공업(누적)'!AC9-'삼성중공업(누적)'!AB9 | AD9: ='삼성중공업(누적)'!AD9-'삼성중공업(누적)'!AC9 | AE9: ='삼성중공업(누적)'!AE9-'삼성중공업(누적)'!AD9 | AF9: ='삼성중공업(누적)'!AF9 | AG9: ='삼성중공업(누적)'!AG9-'삼성중공업(누적)'!AF9 | AH9: ='삼성중공업(누적)'!AH9-'삼성중공업(누적)'!AG9 | AI9: ='삼성중공업(누적)'!AI9-'삼성중공업(누적)'!AH9 | AJ9: ='삼성중공업(누적)'!AJ9 | AK9: ='삼성중공업(누적)'!AK9-'삼성중공업(누적)'!AJ9 | AL9: ='삼성중공업(누적)'!AL9-'삼성중공업(누적)'!AK9 | AM9: ='삼성중공업(누적)'!AM9-'삼성중공업(누적)'!AL9 | AN9: ='삼성중공업(누적)'!AN9 | AO9: ='삼성중공업(누적)'!AO9-'삼성중공업(누적)'!AN9
A10: 파생거래손실 | B10: ='삼성중공업(누적)'!B10 | C10: ='삼성중공업(누적)'!C10-'삼성중공업(누적)'!B10 | D10: ='삼성중공업(누적)'!D10 | E10: ='삼성중공업(누적)'!E10-'삼성중공업(누적)'!D10 | F10: ='삼성중공업(누적)'!F10-'삼성중공업(누적)'!E10 | G10: ='삼성중공업(누적)'!G10-'삼성중공업(누적)'!F10 | H10: ='삼성중공업(누적)'!H10 | I10: ='삼성중공업(누적)'!I10-'삼성중공업(누적)'!H10 | J10: ='삼성중공업(누적)'!J10-'삼성중공업(누적)'!I10 | K10: ='삼성중공업(누적)'!K10-'삼성중공업(누적)'!J10 | L10: ='삼성중공업(누적)'!L10 | M10: ='삼성중공업(누적)'!M10-'삼성중공업(누적)'!L10 | N10: ='삼성중공업(누적)'!N10-'삼성중공업(누적)'!M10 | O10: ='삼성중공업(누적)'!O10-'삼성중공업(누적)'!N10 | P10: ='삼성중공업(누적)'!P10 | Q10: ='삼성중공업(누적)'!Q10-'삼성중공업(누적)'!P10 | R10: ='삼성중공업(누적)'!R10-'삼성중공업(누적)'!Q10 | S10: ='삼성중공업(누적)'!S10-'삼성중공업(누적)'!R10 | T10: ='삼성중공업(누적)'!T10 | U10: ='삼성중공업(누적)'!U10-'삼성중공업(누적)'!T10 | V10: ='삼성중공업(누적)'!V10-'삼성중공업(누적)'!U10 | W10: ='삼성중공업(누적)'!W10-'삼성중공업(누적)'!V10 | X10: ='삼성중공업(누적)'!X10 | Y10: ='삼성중공업(누적)'!Y10-'삼성중공업(누적)'!X10 | Z10: ='삼성중공업(누적)'!Z10-'삼성중공업(누적)'!Y10 | AA10: ='삼성중공업(누적)'!AA10-'삼성중공업(누적)'!Z10 | AB10: ='삼성중공업(누적)'!AB10 | AC10: ='삼성중공업(누적)'!AC10-'삼성중공업(누적)'!AB10 | AD10: ='삼성중공업(누적)'!AD10-'삼성중공업(누적)'!AC10 | AE10: ='삼성중공업(누적)'!AE10-'삼성중공업(누적)'!AD10 | AF10: ='삼성중공업(누적)'!AF10 | AG10: ='삼성중공업(누적)'!AG10-'삼성중공업(누적)'!AF10 | AH10: ='삼성중공업(누적)'!AH10-'삼성중공업(누적)'!AG10 | AI10: ='삼성중공업(누적)'!AI10-'삼성중공업(누적)'!AH10 | AJ10: ='삼성중공업(누적)'!AJ10 | AK10: ='삼성중공업(누적)'!AK10-'삼성중공업(누적)'!AJ10 | AL10: ='삼성중공업(누적)'!AL10-'삼성중공업(누적)'!AK10 | AM10: ='삼성중공업(누적)'!AM10-'삼성중공업(누적)'!AL10 | AN10: ='삼성중공업(누적)'!AN10 | AO10: ='삼성중공업(누적)'!AO10-'삼성중공업(누적)'!AN10
A11: 파생평가이익 | B11: ='삼성중공업(누적)'!B11 | C11: ='삼성중공업(누적)'!C11-'삼성중공업(누적)'!B11 | D11: ='삼성중공업(누적)'!D11 | E11: ='삼성중공업(누적)'!E11-'삼성중공업(누적)'!D11 | F11: ='삼성중공업(누적)'!F11-'삼성중공업(누적)'!E11 | G11: ='삼성중공업(누적)'!G11-'삼성중공업(누적)'!F11 | H11: ='삼성중공업(누적)'!H11 | I11: ='삼성중공업(누적)'!I11-'삼성중공업(누적)'!H11 | J11: ='삼성중공업(누적)'!J11-'삼성중공업(누적)'!I11 | K11: ='삼성중공업(누적)'!K11-'삼성중공업(누적)'!J11 | L11: ='삼성중공업(누적)'!L11 | M11: ='삼성중공업(누적)'!M11-'삼성중공업(누적)'!L11 | N11: ='삼성중공업(누적)'!N11-'삼성중공업(누적)'!M11 | O11: ='삼성중공업(누적)'!O11-'삼성중공업(누적)'!N11 | P11: ='삼성중공업(누적)'!P11 | Q11: ='삼성중공업(누적)'!Q11-'삼성중공업(누적)'!P11 | R11: ='삼성중공업(누적)'!R11-'삼성중공업(누적)'!Q11 | S11: ='삼성중공업(누적)'!S11-'삼성중공업(누적)'!R11 | T11: ='삼성중공업(누적)'!T11 | U11: ='삼성중공업(누적)'!U11-'삼성중공업(누적)'!T11 | V11: ='삼성중공업(누적)'!V11-'삼성중공업(누적)'!U11 | W11: ='삼성중공업(누적)'!W11-'삼성중공업(누적)'!V11 | X11: ='삼성중공업(누적)'!X11 | Y11: ='삼성중공업(누적)'!Y11-'삼성중공업(누적)'!X11 | Z11: ='삼성중공업(누적)'!Z11-'삼성중공업(누적)'!Y11 | AA11: ='삼성중공업(누적)'!AA11-'삼성중공업(누적)'!Z11 | AB11: ='삼성중공업(누적)'!AB11 | AC11: ='삼성중공업(누적)'!AC11-'삼성중공업(누적)'!AB11 | AD11: ='삼성중공업(누적)'!AD11-'삼성중공업(누적)'!AC11 | AE11: ='삼성중공업(누적)'!AE11-'삼성중공업(누적)'!AD11 | AF11: ='삼성중공업(누적)'!AF11 | AG11: ='삼성중공업(누적)'!AG11-'삼성중공업(누적)'!AF11 | AH11: ='삼성중공업(누적)'!AH11-'삼성중공업(누적)'!AG11 | AI11: ='삼성중공업(누적)'!AI11-'삼성중공업(누적)'!AH11 | AJ11: ='삼성중공업(누적)'!AJ11 | AK11: ='삼성중공업(누적)'!AK11-'삼성중공업(누적)'!AJ11 | AL11: ='삼성중공업(누적)'!AL11-'삼성중공업(누적)'!AK11 | AM11: ='삼성중공업(누적)'!AM11-'삼성중공업(누적)'!AL11 | AN11: ='삼성중공업(누적)'!AN11 | AO11: ='삼성중공업(누적)'!AO11-'삼성중공업(누적)'!AN11
A12: 파생평가손실 | B12: ='삼성중공업(누적)'!B12 | C12: ='삼성중공업(누적)'!C12-'삼성중공업(누적)'!B12 | D12: ='삼성중공업(누적)'!D12 | E12: ='삼성중공업(누적)'!E12-'삼성중공업(누적)'!D12 | F12: ='삼성중공업(누적)'!F12-'삼성중공업(누적)'!E12 | G12: ='삼성중공업(누적)'!G12-'삼성중공업(누적)'!F12 | H12: ='삼성중공업(누적)'!H12 | I12: ='삼성중공업(누적)'!I12-'삼성중공업(누적)'!H12 | J12: ='삼성중공업(누적)'!J12-'삼성중공업(누적)'!I12 | K12: ='삼성중공업(누적)'!K12-'삼성중공업(누적)'!J12 | L12: ='삼성중공업(누적)'!L12 | M12: ='삼성중공업(누적)'!M12-'삼성중공업(누적)'!L12 | N12: ='삼성중공업(누적)'!N12-'삼성중공업(누적)'!M12 | O12: ='삼성중공업(누적)'!O12-'삼성중공업(누적)'!N12 | P12: ='삼성중공업(누적)'!P12 | Q12: ='삼성중공업(누적)'!Q12-'삼성중공업(누적)'!P12 | R12: ='삼성중공업(누적)'!R12-'삼성중공업(누적)'!Q12 | S12: ='삼성중공업(누적)'!S12-'삼성중공업(누적)'!R12 | T12: ='삼성중공업(누적)'!T12 | U12: ='삼성중공업(누적)'!U12-'삼성중공업(누적)'!T12 | V12: ='삼성중공업(누적)'!V12-'삼성중공업(누적)'!U12 | W12: ='삼성중공업(누적)'!W12-'삼성중공업(누적)'!V12 | X12: ='삼성중공업(누적)'!X12 | Y12: ='삼성중공업(누적)'!Y12-'삼성중공업(누적)'!X12 | Z12: ='삼성중공업(누적)'!Z12-'삼성중공업(누적)'!Y12 | AA12: ='삼성중공업(누적)'!AA12-'삼성중공업(누적)'!Z12 | AB12: ='삼성중공업(누적)'!AB12 | AC12: ='삼성중공업(누적)'!AC12-'삼성중공업(누적)'!AB12 | AD12: ='삼성중공업(누적)'!AD12-'삼성중공업(누적)'!AC12 | AE12: ='삼성중공업(누적)'!AE12-'삼성중공업(누적)'!AD12 | AF12: ='삼성중공업(누적)'!AF12 | AG12: ='삼성중공업(누적)'!AG12-'삼성중공업(누적)'!AF12 | AH12: ='삼성중공업(누적)'!AH12-'삼성중공업(누적)'!AG12 | AI12: ='삼성중공업(누적)'!AI12-'삼성중공업(누적)'!AH12 | AJ12: ='삼성중공업(누적)'!AJ12 | AK12: ='삼성중공업(누적)'!AK12-'삼성중공업(누적)'!AJ12 | AL12: ='삼성중공업(누적)'!AL12-'삼성중공업(누적)'!AK12 | AM12: ='삼성중공업(누적)'!AM12-'삼성중공업(누적)'!AL12 | AN12: ='삼성중공업(누적)'!AN12 | AO12: ='삼성중공업(누적)'!AO12-'삼성중공업(누적)'!AN12
